Workbook
Name CalcMethod: 'B. Project Scope'!#REF!
Name CalcMethod: 'B. Project Scope'!#REF!
Name CalcMethod: '[1]B. Project Scope'!#REF!
Name CalcMethod: '[1]B. Project Scope'!#REF!
Name CalcMethod: '[1]B. Project Scope'!#REF!
Name CalcMethod: '[2]B. Project Scope'!#REF!
Name CalcMethod: '[1]B. Project Scope'!#REF!
Name CalcMethod: 'B. Project Scope'!#REF!
Name CalcMethod: '[3]NRCC B. Project Scope'!#REF!
Name CalcMethod: '[1]B. Project Scope'!#REF!
Name CalcMethod: '[1]B. Project Scope'!#REF!
Name CalcMethod: '[1]B. Project Scope'!#REF!
Name CalcMethod: 'B. Project Scope'!#REF!
Name TEST: '[4]B. Project Scope'!#REF!

Sheet Change Log
A1: Date | B1: Table | C1: Description | D1: Color
A2: 45412 | B2: Footer | C2: Change date in footer | D2: Yellow with red text
A3: 45412 | B3: Signature Block | C3: Add "Responsible Person Scope" field | D3: Yellow with red text
A4: 45412 | B4: F- Lighting Schedule | C4: Add exemption to F.09 | D4: Yellow with red text
A5: 45080 | B5: H - Controls | C5: Add motion sensor dropdown to H.04 | D5: Yellow with red text
A6: 45469 | B6: Signature Block | C6: Added AEA and replaced "HERS" with "ECC" | D6: Yellow with red text
A7: 45471 | B7: Table A | C7: Modify building occupancy type fields | D7: Yellow with red text
A10: CEC notes
A11: 45581 | B11: I - Allowance General | C11: Inserted a copy of Table 140.7-A (2025 Code 15Day). Also added a note about the table.
A12: 45581 | B12: A- General Info | C12: Inserted a copy of Table 10-114-A of the 15-Day language of the 2025 Code development.
A13: 45596 | B13: H - Lighting Controls | C13: See Simon's notes on Motion Sensor Dropdown | D13: Red/Black
A14: 45596 | B14: N - Exist. Cond. | C14: See Simon's note on Field 06 - Existing Watts
A15: 45600 | B15: H. Lighting Controls | C15: Edited/added on "Outdoor Lighting Controlled from Inside Multifamily Dwelling Units" | D15: Green/red

Sheet Table Sequence
A1: Label | B1: Table Title | C1: Trigger within:
A2: Table A | B2: General Information | C2: ALWAYS
A3: Table B | B3: Project Scope | C3: ALWAYS
A4: Table C | B4: Compliance Results | C4: ALWAYS
A5: Table D | B5: Exceptional Conditions | C5: ALWAYS
A6: Table E | B6: Additional Remarks | C6: ALWAYS
A7: Table F | B7: Outdoor Lighting Fixture Schedule | C7: Table B
A8: Table G | B8: Shielding Requirements (BUG) | C8: Table F
A9: Table H | B9: Outdoor Lighting Controls | C9: Table B
A10: Table I | B10: General Hardscape Lighting Power Allowance (per §140.7) | C10: Table B
A11: Table J | B11: Additional Lighting Allowance: Per Application | C11: Table I
A12: Table K | B12: Additional Lighting Allowance: Sales Frontage | C12: Table I
... A18: - | B18: Signature Page | C18: ALWAYS

Sheet Hyperlinks
A1: Label | B1: Tables
A2: §110.9 | B2: 1st page Header
A3: §130.0 | B3: 1st page Header
A4: §130.2 | B4: 1st page Header, F, G, H
A5: §140.7 | B5: 1st page Header, B, C, F, I, J, K, L, M
A6: §141.0(b)2L | B6: 1st page Header, B, C, N
A7: Ch. 6 of Nonresidential Compliance Manual | B7: Table Tip for Table A
A8: §140.7(d)1 | B8: C
A9: §140.7(d)2 | B9: C
A10: §130.2(c)1 | B10: H
A11: §130.2(c)2 | B11: H
A12: §130.2(c)3 | B12: H
... A20: NRCI location on CEC website | B20: O
A21: §141.0(b)2L
A22: Title 24 Part 1 §10-114
A23: §140.7(a)
A24: §130.0(c)
A25: §130.2b

Sheet NRCC Headers
B1: User input | D1: auto calculated | H1: From another Table | K1: From look up table
A2: STATE OF CALIFORNIA
A3: Outdoor Lighting
A4: NRCC-LTO-E | I4: CALIFORNIA ENERGY COMMISSION
A5: CERTIFICATE OF COMPLIANCE | K5: NRCC-LTO-E
A6: This document is used to demonstrate compliance with requirements in §110.9, §130.0, §130.2, §140.7, and §141.0(b)2L for outdoor lighting scopes using the prescriptive path for nonresidential and hotel/motel occupancies. It is also used to document compliance with requirements in §160.5, §170.2(e)6, §180.1(a) and §180.2(b)4Bv for outdoor lighting scopes using the prescriptive path for multifamily and mixed-use occupancies. Multifamily includes dormitory and senior living facilities.
A7: Project Name: | I7: Report Page: | K7: Page 1 of ??
A8: Project Address: | I8: Date Prepared:
B10: This is a heading. The project name, address and date prepared should be a user input on the first page, but that should populate the heading on all other pages.
A13: STATE OF CALIFORNIA
A14: Outdoor Lighting
A15: NRCC-LTO-E | I15: CALIFORNIA ENERGY COMMISSION
A16: CERTIFICATE OF COMPLIANCE | K16: NRCC-LTO-E
A17: Project Name: | I17: Report Page: | K17: Page 1 of ??
A18: Project Address: | I18: Date Prepared:

Sheet LMCC Headers
B1: User input | D1: auto calculated | H1: From another Table | K1: From look up table
A2: STATE OF CALIFORNIA
A3: Outdoor Lighting
A4: LMCC-LTO-01-E | I4: CALIFORNIA ENERGY COMMISSION
A5: CERTIFICATE OF COMPLIANCE | K5: LMCC-LTO-01-E
A6: This document is used to demonstrate compliance with requirements in §110.9, §130.0, §130.2, §140.7, and §141.0(b)2L for outdoor lighting scopes using the prescriptive path for nonresidential and hotel/motel occupancies in low-rise multifamily mixed-use buildings. It is also used to document compliance with requirements in §160.5, §170.2(e)6, §180.1(a) and §180.2(b)4Bv for outdoor lighting scopes using the prescriptive path for low-rise multifamily occupancies. Multifamily includes dormitory and senior living facilities.
A7: Project Name: | I7: Report Page: | K7: Page 1 of ??
A8: Project Address: | I8: Date Prepared:
B10: This is a heading. The project name, address and date prepared should be a user input on the first page, but that should populate the heading on all other pages.
A13: STATE OF CALIFORNIA
A14: Outdoor Lighting
A15: LMCC-LTO-01-E | I15: CALIFORNIA ENERGY COMMISSION
A16: CERTIFICATE OF COMPLIANCE | K16: LMCC-LTO-01-E
A17: Project Name: | I17: Report Page: | K17: Page 1 of ??
A18: Project Address: | I18: Date Prepared:

Sheet NRCC Footer
B1: User input | D1: auto calculated | G1: From another Table | J1: From look up table
A4: Footer for every page:
A6: Registration Number: | E6: Registration Date/Time: | I6: Registration Provider:
E7: Report Version: | I7: Compliance ID:
E8: Schema Version: | I8: Report Generated:
A9: CA Building Energy Efficiency Standards - 2025 Nonresidential Compliance

Sheet Sheet1
B1: User input | D1: auto calculated | G1: From another Table | J1: From look up table
A4: Footer for every page:
A6: Registration Number: | E6: Registration Date/Time: | I6: Documentation Software
E7: Report Version: | I7: Compliance ID:
E8: Schema Version: | I8: Report Generated:
A9: CA Building Energy Efficiency Standards - 2025 Low-rise Multifamily Compliance

Sheet A. General Info
C1: User input | E1: auto calculated | I1: From another Table | L1: From look up table
A3: A. GENERAL INFORMATION
A4: 01 | B4: Project Location (city) | G4: 04 | H4: Total Illuminated Hardscape Area (ft2)
A5: 02 | B5: Climate Zone
A6: 03 | B6: Outdoor Lighting Zone per Title 24, Part 1 §10-114 or as designated by Authority Having Jurisdiction (AHJ):
A7: ¨ | B7: LZ-0: Very Low- Undeveloped Parkland | E7: ¨ | F7: LZ-2: Moderate- Urban Areas | G7: ¨ | H7: LZ-4: High-Must be reviewed by CA Energy Commission for Approval
A8: ¨ | B8: LZ-1: Low- Rural Areas | E8: ¨ | F8: LZ-3: Moderately High- Urban Areas
A9: 05 | B9: Occupancy Types within Project:
F17: If user selects MF occupancy, (even if mixed-use) the MF subtable in I is the only ones that applies.

Sheet B. Project Scope
C1: User input | E1: auto calculated | I1: From another Table | L1: From look up table
A3: B. PROJECT SCOPE
A4: This table includes outdoor lighting systems that are within the scope of the permit application and are demonstrating compliance using the prescriptive path outlined in §140.7/§170.2(e)6 or §141.0(b)2L/§180.2(b)4Bv for alterations.
A5: My project consists of:
A6: 01 | D6: 02
A7: ¨ | B7: New Lighting System | D7: Must Comply with Allowances from §140.7/§170.2(e)6.
A8: ¨ | B8: Altered Lighting System | D8: Is your alteration increasing the connected lighting load (Watts)? | H8: o Yes | I8: o No
A9: 03 | E9: 04 | F9: 05
A10: % of Existing Luminaires Being Altered1 | E10: Sum Total of Luminaires Being Added or Altered | F10: Calculation Method
A11: o < 10% | C11: o ≥ 10% and < 50% | D11: o ≥ 50% | F11: Dropdown, see below for list (custom)
A12: Please proceed to Table F. Outdoor Lighting Fixture Schedule to define the project's luminaires.
A13: 1 FOOTNOTES: % of Existing Luminaires Being Altered = (Sum Total of Luminaires Being Added or Altered / Existing Luminaires within the Scope of the Permit Application) x 100
E15: This is the dropdown if > 50% is clicked in column 03 >> | F15: Calculation Method Dropdown
F16: Calculated Allowance per §140.7/§170.2(e)6 | J16: << triggers Table I.
F17: 40% Reduced Wattage Exception per §141.0(b)2L/§180.2(b)4Bv | J17: << triggers Table N.
E19: This is the dropdown if "> 10% and < 50%" or "<10%" is clicked in column 03 >> | F19: Calculation Method Dropdown
F20: Not Increasing Existing Power Method per §141.0(b)2L/§180.2(b)4Bv | J20: << triggers Table N.

Sheet C. Compliance
B1: User input | E1: auto calculated | I1: From another Table | M1: From look up table
A4: C. COMPLIANCE RESULTS
A5: Results in this table are automatically calculated from data input and calculations in Tables G through N. Note: If any cell on this table says "COMPLIES with Exceptional Conditions" refer to Table D. Exceptional Conditions for guidance or see the applicable Table referenced below.
A6: Calculation of Total Allowed Lighting Power (Watts) §140.7/§170.2(e)6 or §141.0(b)2L/§180.2(b)4Bv | M6: Compliance Results
A7: 01 | B7: + | C7: 02 | D7: + | E7: 03 | F7: + | G7: 04 | H7: + | I7: 05 | J7: OR | K7: 06 | L7: = | M7: 07 | N7: > | O7: 08 | P7: 09
A8: General Hardscape Allowance §140.7(d)1/ §170.2(e)6 | C8: Per Application §140.7(d)2/ §170.2(e)6 | E8: Sales Frontage §140.7(d)2 | G8: Ornamental §140.7(d)2/ §170.2(e)6 | I8: Per Specific Area §140.7(d)2/ §170.2(e)6 | K8: Existing Power Allowance §141.0(b)2L/ §180.2(b)4Bv | M8: Total Allowed (Watts) | O8: Total Actual (Watts) | P8: 07 Must be > 08
A9: (See Table I) | C9: (See Table J) | E9: (See Table K) | G9: (See Table L) | I9: (See Table M) | K9: (See Table N) | O9: (See Table F)
B10: + | C10: ='J. Per Application'!J12 -> sum of column 10 (J10) | D10: + | E10: ='K. Sales Frontage'!I12 -> sum of column 09 (K09) | F10: + | G10: ='L. Ornamental'!I12 -> sum of column 09 (L09) | H10: + | I10: ='M. Per Specific Area'!J12 -> sum of column 10 (M10) | J10: OR | K10: ='N. Exist. Cond.'!J11 -> 0 | L10: = | M10: =A10+C10+E10+G10+I10+K10 -> #VALUE! | N10: > | O10: ='F. Lighting Schedule'!L10 -> sum of column 08 | P10: COMPLIES or DOES NOT COMPLY
A11: Shielding Compliance (See Table G for Details) | P11: "COMPLIES" or "DOES NOT COMPLY" or "Not Applicable"
A12: Controls Compliance (See Table H for Details) | P12: "COMPLIES with Exceptional Conditions" or "COMPLIES" or "DOES NOT COMPLY"

Sheet D. Exceptional Conditions
B1: User input | E1: auto calculated | I1: From another Table | M1: From look up table
A3: D. EXCEPTIONAL CONDITIONS
A4: This table is auto-filled with uneditable comments because of selections made or data entered in tables throughout the form.
B8: Comment:
B9: The note about making changes in the NRCI/NRCA tables need to show up.
B10: Table A indicates LZ-4 as the lighting zone for this project. This designation requires approval by the CA Energy Commission.
B11: Total Hardscape Area in Table A does not match the areas entered in Table I. Please review for compliance.
B12: Table D. indicates a dropdown selection with a * requiring a note describing the compliance approach, but no notes have been entered.
B13: Table N. indicates a dropdown selection with a * requiring a note describing the compliance approach, but no notes have been entered.
B14: Linear lighting has been indicated on Table F. For these luminaires, wattage reported in F03 is in “W/lf” and Total Number Luminaires reported in F05 indicates total linear feet (lf) of that luminaire type.

Sheet E. Additional Remarks
B1: User input | E1: auto calculated | I1: From another Table | M1: From look up table
A4: E. ADDITIONAL REMARKS
A5: This table includes remarks made by the permit applicant to the Authority Having Jurisdiction.

Sheet F. Lighting Schedule
B1: User input | D1: auto calculated | H1: From another Table | M1: From look up table
A3: F. OUTDOOR LIGHTING FIXTURE SCHEDULE
A4: For new or altered lighting systems demonstrating compliance with §140.7/§170.2(e)6 all luminaires being installed and any existing luminaires remaining or being moved within the spaces covered by the permit application are included in the Table below. For altered lighting systems using the Existing Power method per §141.0(b)2L, only new luminaires being installed and replacement luminaires being installed as part of the project scope are included (ie, existing luminaires remaining or existing luminaires being moved are not included). Outdoor lighting attached to multifamily buildings and controlled from the inside of a dwelling unit are included in Table H. and are not included here. All other multifamily outdoor lighting is included here.
A5: Designed Wattage:
A6: 01 | B6: 02 | D6: 03 | E6: 04 | F6: 05 | J6: 06 | K6: 07 | L6: 08 | M6: 09 | N6: 10
A7: Name or Item Tag | B7: Complete Luminaire Description | D7: Watts per luminaire1, 2 | E7: How Wattage is Determined | F7: Total Number Luminaires2 | J7: Luminaire Status3 | K7: Excluded per §140.7(a)/ §170.2(e)6A | L7: Design Watts | M7: Cutoff Req. ≥ 6,200 initial lumen output §130.2(b)/§160.5(c)14 | N7: Field Inspector
N8: Pass | O8: Fail
C9: o Linear | E9: Dropdown, See below for list. | J9: Dropdown, See below for list. | K9: o | M9: Dropdown, See below for list. | N9: o | O9: o
K10: Total Designed Watts: | L10: sum of column 08
A11: * NOTES: Selections with a * require a note in the space below explaining how compliance is achieved.
A12: EX: Luminaire is lighting a statue; EXCEPTION 2 to §130.2(b).
A13: If the users select options with a *, the Name or Item Tag (uneditable) should show up in Notes section. If users unselect options with a *, the note should dissapear. | B13: This box should work just like the one on the indoor lighting form except the text in the notes box when it's triggered should read "Explain here why item with asterisk complies"
A14: 1 FOOTNOTES: Authority Having Jurisdiction may ask for Luminaire cut sheets to confirm wattage used for compliance per §130.0(c)/§160.5(b).
A15: 2 For linear luminaires, wattage should be indicated as W/lf instead of Watts/luminaire. Total linear feet for the luminaire should be indicated in column 05 instead of number of luminaires.
A16: 3 Select “New” for new luminaires in a new outdoor lighting project or for added luminaires in an alteration. Select “Altered” for replacement luminaires in an alteration. Select “Existing to Remain” for existing luminaires within the project scope that are not being altered and are remaining. Select “Existing Reinstalled” for existing luminaires which are being removed and reinstalled as part of the project scope
A17: 4 Compliance with mandatory shielding requirements is required for luminaires with initial lumen output ≥ 6,200 unless exempted by §130.2(b)/§160.5(c).
E19: How Wattage is Determined Dropdown | J19: Luminaire Status Dropdown | M19: Cutoff Req. ≥ 6,200 initial lumen output §130.2(b)3
E21: NA8 Default | J21: New | M21: Yes | N21: << triggers Table G.
E22: Mfr. Spec1 | J22: Altered | M22: NA: <6,200 lumens
E23: Other* | J23: Exist. Remain | M23: NA: Ltg Zone LZ-0
J24: Exist. Reinstalled | M24: NA: Signage
M25: NA: Façade, monument, art, statue, bridge, public art
M26: NA: Not permitted by H&LS
M27: NA: Temporary lighting
M28: NA: Replacement of pole-mounted per §130.2(b)/§160.5(c)
M29: NA: Illuminate public right-of-way
M30: NA: Controlled by dwelling unit/guest rm
M31: NA: Luminaire exempt from CalGreen §5.106.8 and 140.7(a)

Sheet G. BUG
B1: User input | L1: auto calculated | Q1: From another Table | U1: From look up table
A3: G. SHIELDING REQUIREMENTS (BUG)
A4: This table includes fixtures of ≥ 6,200 initial luminaire lumens indicated on Table F as needing to comply with Shielding Requirements. Maximum lumens can be found in Title 24, Part 11, Section 5.106.8. | W4: No changes to BUG ratings in Table from 2019 Part 6 to 2022 Part 6
A5: 01 | B5: 02 | C5: 03 | F5: 04 | G5: 05 | H5: 06 | J5: 07 | K5: 08 | L5: 09 | O5: 10 | P5: 11 | Q5: 12
A6: Name or Item Tag | B6: Complete Luminaire Description | C6: Backlight Rating2 | H6: Uplight Rating 2 | L6: Glare Rating2 | Q6: Field Inspector
C7: Mounting Height from Property Line1 | F7: Max Allowable Backlight Rating3 | G7: Backlight Rating Per Design | H7: Lighting Type | J7: Max Allowable Uplight Rating3 | K7: Uplight Rating Per Design | L7: Mounting Height from Property Line1 | O7: Max Allowable Glare Rating3 | P7: Glare Rating Per Design | Q7: Pass | R7: Fail
A8: (autofill from Table F) | B8: (autofill from Table F) | C8: dropdown | H8: dropdown | L8: dropdown | Q8: o | R8: o
A10: 1 FOOTNOTES: Mounting Height is labeled MH in this table
A11: 2 Authority having jurisdiction may ask for luminaire cut sheets or other documentation to confirm luminaire type, backlight, uplight,and glare ratings used for compliance per §130.2(b)/§160.5(c).
A12: 3 BUG ratings with a lower number than the 'Max Allowable' are compliant. Ex. If Max Allowable is Bug Rating is B4, then B0, B1, B2, B3 and B4 are all compliant.
C14: Mounting Height drop down | H14: dropdown | L14: Mounting Height drop down
C15: > 2 MH from property line | H15: Area Lighting | L15: > 2 MH from property line
C16: Back hemisphere 1-2 MH from prop line | H16: All Other (including decorative) | L16: Front hemisphere 1-2 MH from prop line
C17: Back hemisphere 0.5-1 MH from prop line | L17: Front hemisphere 0.5-1 MH from prop line
C18: Back hemisphere < 0.5 MH from prop line | L18: Front hemisphere < 0.5 MH from prop line

Sheet H. Lighting Controls
B1: User input | E1: auto calculated | I1: From another Table | P1: From look up table
A4: H. OUTDOOR LIGHTING CONTROLS
A5: This table demonstrates compliance with controls requirements for all new or altered luminaires installed as part of the permit application. For alteration projects, luminaires which are existing to remain (ie untouched) and luminaires which are removed and reinstalled (wiring only) do not need to be included in this table even if they are within the spaces covered by the permit application. Outdoor lighting for nonresidential buildings, parking garages and common service areas in multifamily buildings must be documented seperately from outdoor lighting attached to multifamily buildings and controlled from the inside of a dwelling unit.
A6: Mandatory Controls for Nonresidential Occupancies, Parking Garages & Common Service Areas in Multifamily Buildings
A7: 01 | B7: 02 | J7: 03 | R7: 04 | W7: 05
A8: Area Description | B8: Shut-Off | J8: Auto-Schedule | R8: Motion Sensor | W8: Field Inspector
B10: §130.2(c)1/§160.5(c) | J10: §130.2(c)2/§160.5(c) | R10: §130.2(c)3/§160.5(c) | W10: Pass | X10: Fail
B11: See dropdown | J11: See dropdown | R11: See dropdown | W11: o | X11: o
B14: Shutoff Dropdown | F14: Auto-schedule Dropdown | R14: Motion Sensor Dropdown
B15: Photocontrol | F15: Yes | R15: Yes
B16: Astronomical Timer | F16: Yes-EMCS | R16: NA: Façade, etc. ≤ 24ft
B17: Other Control Technology | F17: NA: Not permitted by H&LS | R17: NA: > 24ft
B18: NA: Not permitted by H&LS | F18: NA: Lighting in Tunnels | R18: NA: Historical Building Lighting
B19: NA: Lighting in Tunnels | F19: NA: MF Complying w §160.5(a) | R19: NA: Not permitted by H&LS
B20: NA: MF Complying w §160.5(a) | F20: NA: Parking or Sales Lots >24 ft/all other at any height | R20: NA: Lighting in Tunnels
R21: NA: Each Luminaires < 40 Watts
R22: NA: Parking Lot Each Luminaires < 78 Watts
R23: NA: Temporary Lighting
R24: NA: Regulated by FAA or Coast Guard
R25: NA: Lighting for Public Roadways
P26: 1 | R26: NA: Athletic Fields/Playground Lighting
R27: NA: Industrial Sites Lighting
R28: NA: Public Monument Lighting
R29: NA: Sign Lighting
R30: NA: Landscape Lighting
R31: NA: Stairs, Wheelchair Lift/Ramp Lighting
R32: NA: Theme Park Special Effect Lighting
R33: NA: Outdoor Theatre
R34: NA: MF Complying w §160.5(a)
R35: NA: Ornamental
R36: NA: Outdoor Dining
A37: THIS ENTIRE SUBTABLE IS NEW FOR 2022 and is triggered if user selects "Multifamily/Mixed-use" in A05
A38: Outdoor Lighting Controlled from Inside Multifamily Dwelling Units
A39: This table documents compliance with mandatory requirements for outdoor lighting attached to multifamily buildings and controlled from the inside of a dwelling unit per §160.5(a). Outdoor lighting systems in common use areas providing shared provisions for living, eating, cooking, or sanitation to dwelling units that would otherwise lack these provisions may document compliance with §160.5(a) in this table or may document compliance with outdoor lighting for nonresidential occupancies.
A40: 01 | B40: 02 | H40: 03 | M40: 04
A41: Space Name | B41: Compliant Light Sources1,2 §160.5(a)1 | H41: Mandatory Controls §160.5(a) | M41: Recessed Downlights3 §160.5(a)1C
H42: Shut-Off
H43: see dropdown below | M43: i. Shall not contain screw base lamp sockets; and ii. Have a label that certifies the luminaire is airtight with air leakage less than 2.0 cfm at 75 Pascals when tested in accordance with ASTM E283. An exhaust fan housing with integral light shall not be required to be certified airtight; and iii. Be sealed with a gasket or caulk between the luminaire housing and ceiling, and have all air leak paths between conditioned and unconditioned spaces sealed with a gasket or caulk, or be installed per manufacturer’s instructions to maintain airtightness between the luminaire housing and ceiling; and iv. Meet the clearance and installation requirements of California Electrical Code Article 410.116 for recessed luminaires; and v. Lamps and other separable light sources in enclosed or recessed luminaires shall be in compliance with the JA8 elevated temperature requirements, including marking requirements, shall not be installed in enclosed or recessed luminaires.
H44: see dropdown below
H45: see dropdown below
...

Sheet I. Allowance General 
C1: User input | E1: auto calculated | I1: From another Table | M1: From look up table
A3: I. LIGHTING POWER ALLOWANCE (per §140.7/170.2(e))
A4: This table includes areas using the allowance calculations per §140.7/§170.2(e)6. General Hardscape Allowance is per Table 140.7-A/ Table 170.2-R while "Use it or lose it" Allowances are per Table 140.7-B/Table 170.2-S. Luminaires that qualify for one of the "Use it or lose it" allowances shall not qualify for another "Use it or lose it" allowance. Outdoor lighting attached to multifamily buildings and controlled from the inside of a dwelling unit are included in Table H. and are not included here. All other multifamily outdoor lighting is included here. | F4: 01
F5: ¨ General Hardscape Allowance | G5: "Use it or lose it" Allowances (select all that apply)
G6: ¨ Per Application | H6: ¨ Sales Frontage | I6: ¨ Ornamental | J6: ¨ Per Specific Area
F8: Table I (below) | G8: Table J | H8: Table K | I8: Table L | J8: Table M
A9: Calculated General Hardscape Lighting Power Allowance per Table 140.7-A for Nonresidential & Hotel/Motel
A10: 02 | D10: 03 | E10: 04 | F10: 05 | G10: 06 | H10: 07 | I10: 08 | J10: 09
A11: Area Description | D11: Area Wattage Allowance (AWA) | G11: Linear Wattage Allowance (LWA) | J11: Total General AWA + LWA (Watts)
D12: Illuminated Area (ft2) | E12: Allowed Density (W/ft2) | F12: Area Allowance (Watts) | G12: Perimeter Length (lf) | H12: Allowed Density (W/lf) | I12: Linear Allowance (Watts)
F13: =D13*E13 -> 0 | I13: =G13*H13 -> 0 | J13: =F13+I13 -> 0
A14: 1 FOOTNOTES: Number of entrances to parking areas, trail heads, fee payment kiosks, outhouses and toilet facilities on site where lighting is within project scope. | I14: Initial Wattage Allowance for Entire Site (Watts):
F15: Instances of Initial Wattage Allowance (LZ 0 only)1
F16: Total General Hardscape Allowance (Watts): | J16: sum of col09+(IWA*instances)
A18: Calculated General Hardscape Lighting Power Allowance per Table 170.2-R for Multifamily & Multifamily Mixed-Use
A19: 02 | E19: 03 | G19: 04 | I19: 05
A20: Area Description | E20: Area Wattage Allowance (AWA)
E21: Illuminated Area (ft2) | G21: Allowed Density (W/ft2) | I21: Area Allowance (Watts)
I22: =E22*G22 -> 0 | M22: VALUES IN TABLE 140.7-A changed for 2022. Please update accordingly. (This is from 45 day language, need to confirm once adopted) | AD22: CEC Note: There is no change to the values of Table 140.7-A of the 2025 Energy Code.
A23: 1 FOOTNOTES: Number of entrances to parking areas, trail heads, fee payment kiosks, outhouses and toilet facilities on site where lighting is within project scope. | D23: Initial Wattage Allowance for Entire Site (Watts):
D24: Instances of Initial Wattage Allowance (LZ 0 only)1
D25: Total General Hardscape Allowance (Watts): | J25: sum of col05 (AWA) + (G22 (IWA)*instances)

Sheet J. Per Application
C1: User input | E1: auto calculated | I1: From another Table | M1: From look up table
A3: J. LIGHTING ALLOWANCE: PER APPLICATION
A4: This table includes areas using the wattage allowance per application from Table-140.7-B/Table 170.2-S.
A5: 01 | B5: 02 | C5: 03 | D5: 04 | E5: 05 | F5: 06 | G5: 07 | H5: 08 | I5: 09 | J5: 10
A6: Area Description | B6: Application per Table 140.7-B1 | C6: CALCULATED ALLOWANCE (Watts) | F6: DESIGN WATTS | J6: Additional Allowance (Watts)
C7: # of Locations | D7: Allowance per Location (Watts)2 | E7: Extra Allowance (Watts) | F7: Luminaire Name or Item Tag | G7: Watts per Luminaire3 | H7: # of Luminaires3 | I7: Design Watts
B8: Dropdown, see below for list | D8: See Table 140.7-B | E8: =C8*D8 -> #VALUE! | F8: Dropdown from Table F. | G8: From table F. | I8: =G8*H8 -> #VALUE!
F9: Dropdown from Table F. | G9: From table F. | I9: =G9*H9 -> #VALUE!
E10: Total Design Watts for this Area: | I10: sum of column 09 for the area | J10: smaller of J05 or total design watts for area (J09)
A11: 1 FOOTNOTES: Primary entrance applications are only available for senior care facilities, healthcare facilities, police stations, hospitals, fire stations, and emergency vehicle facilities. | I11: Add Luminaire
A12: 2 The Allowance per Location for ATMs is 100W for the first ATM and 35W for each additional per Table 140.7-B/Table 170.2-S. | I12: Total Allowance (Watts) All Areas: | J12: sum of column 10 (J10) | L12: NO UPDATES FOR 2022 & SAME FOR MF
A13: 3 For luminaires indicated in Table F as linear, wattage in column 07 is W/lf instead of Watts/luminaire. Total linear feet for the luminaire should be indicated in column 08 instead of number of luminaires.
B15: Application per Table 140.7-B dropdown
B16: Bldg Entrance/ Exit
B17: Primary Entrance (Special)
B18: Drive up Window
B19: Uncovered Fuel Dispenser
B20: ATM Machine

Sheet K. Sales Frontage
B1: User input | D1: auto calculated | H1: From another Table | L1: From look up table
A3: K. LIGHTING ALLOWANCE: SALES FRONTAGE
A4: This table includes areas using the wattage allowance for Outdoor Sales Frontage from Table-140.7-B. This allowance may be used for one or two frontage side(s) per site.
A5: 01 | B5: 02 | C5: 03 | D5: 04 | E5: 05 | F5: 06 | G5: 07 | H5: 08 | I5: 09
A6: Area Description | B6: CALCULATED ALLOWANCE (Watts) | E6: DESIGN WATTS | I6: Additional Allowance (Watts)
B7: Linear ft. of Sales Frontage (lf) | C7: Allowed Density (W/lf) | D7: Extra Allowance (Watts) | E7: Luminaire Name or Item Tag | F7: Watts per Luminaire1 | G7: # of Luminaires1 | H7: Design Watts
C8: See Table 140.7-B | D8: =B8*C8 -> #VALUE! | E8: Dropdown from Table F. | F8: From table F. | H8: =F8*G8 -> #VALUE!
E9: Dropdown from Table F. | F9: From table F. | H9: =F9*G9 -> #VALUE!
A10: 1 FOOTNOTES: For luminaires indicated in Table F as linear, wattage in column 06 is W/lf instead of Watts/luminaire. Total linear feet for the luminaire should be indicated in column 07 instead of number of luminaires. | E10: Total Design Watts for this Area: | H10: sum of column 08 for the area | I10: smaller of K04 or total design watts for area (K08)
H11: Add Luminaire | N11: NO UPDATES FOR 2022 & DOES NOT APPLY TO MF
H12: Total Allowance (Watts) All Areas: | I12: sum of column 09 (K09)

Sheet L. Ornamental
B1: User input | D1: auto calculated | H1: From another Table | L1: From look up table
A3: L. LIGHTING ALLOWANCE: ORNAMENTAL
A4: This table includes all ornamental luminaires within the scope of the permit application to calculate the allowance per Table 140.7-B/Table 170.2-S.
A5: 01 | B5: 02 | C5: 03 | D5: 04 | E5: 05 | F5: 06 | G5: 07 | H5: 08 | I5: 09
A6: Area Description | B6: CALCULATED ALLOWANCE (Watts) | E6: DESIGN WATTS | I6: Additional Allowance (Watts)
B7: Illuminated Area (ft2) | C7: Allowed Density (W/ft2) | D7: Extra Allowance (Watts) | E7: Luminaire Name or Item Tag | F7: Watts per Luminaire1,2 | G7: # of Luminaires2 | H7: Design Watts | N7: NO VALUE UPDATES FOR 2022, ONLY CHANGE FOR FOOTNOTE 1 & SAME FOR MF
A8: Total Illuminated Hardscape Area for the Site | B8: ='A. General Info'!J4:K5 -> #VALUE! | C8: See Table 140.7-B | D8: =B8*C8 -> #VALUE! | E8: Dropdown from Table F. | F8: From table F. | H8: =F8*G8 -> #VALUE!
E9: Dropdown from Table F. | F9: From table F. | H9: =F9*G9 -> #VALUE!
D10: Total Design Watts for this Area: | H10: sum of column 08 for the area | I10: smaller of L04 or L08
H11: Add Luminaire
H12: Total Allowance (Watts) Ornamental: | I12: sum of column 09 (L09)
A13: 1 FOOTNOTES: Luminaires qualifying for this allowance shall be rated < 50W and shall be post-top luminaires, lanterns, pendants or chandeliers.
A14: 2 For luminaires indicated in Table F as linear, wattage in column 06 is W/lf instead of Watts/luminaire. Total linear feet for the luminaire should be indicated in column 07 instead of number of luminaires.

Sheet M. Per Specific Area
C1: User input | E1: auto calculated | I1: From another Table | M1: From look up table
A3: M. LIGHTING ALLOWANCE: PER SPECIFIC AREA
A4: This table includes areas using the wattage allowance per specific area type from Table 140.7-B/Table 170.2-S. More than one specific area allowance may be taken in a single project, if applicable. However, multiple specific area allowances may not be taken for the exact same area on the site.
A5: 01 | B5: 02 | C5: 03 | D5: 04 | E5: 05 | F5: 06 | G5: 07 | H5: 08 | I5: 09 | J5: 10
A6: Area Description | B6: Specific Area Type per Table 140.7-B | C6: CALCULATED ALLOWANCE (Watts) | F6: DESIGN WATTS | J6: Additional Allowance (Watts)
C7: Specific Area (ft2)1 | D7: Allowed Density (W/ft2) | E7: Extra Allowance (Watts) | F7: Luminaire Name or Item Tag | G7: Watts per Luminaire2 | H7: # of Luminaires2 | I7: Design Watts
B8: Dropdown, see below for list | D8: See Table 140.7-B | E8: =C8*D8 -> #VALUE! | F8: Dropdown from Table F. | G8: From table F. | I8: =G8*H8 -> #VALUE!
F9: Dropdown from Table F. | G9: From table F. | I9: =G9*H9 -> #VALUE! | N9: ADDED ALLOWANCE FOR SECURITY CAMERAS FOR 2022, SEE LAST IN TABLE. SAME FOR MF!
A10: 1 FOOTNOTES: See Table 140.7-B/Table 170.2-S for the rules for calculating the specific areas (ft2) for these additional lighting allowances. | E10: Total Design Watts for this Area: | I10: sum of column 09 for the area | J10: smaller of M05 or total design watts for area (M09)
A11: 2 For luminaires indicated in Table F as linear, wattage in column 07 is W/lf instead of Watts/luminaire. Total linear feet for the luminaire should be indicated in column 08 instead of number of luminaires. | I11: Add Luminaire
I12: Total Allowance (Watts) All Areas: | J12: sum of column 10 (M10)
B14: Spec. Area per Table 140.7-B dropdown
A15: does not show up for LZ1>> | B15: Bldg Façade
B16: Outdoor Sales Lot
B17: Service Station Hardscape
B18: Service Station Canopy
A19: does not show up for LZ1>> | B19: Sales Canopies
B20: Non-sales Canopies/ Tunnels
B21: Guard Stations
A22: does not show up for LZ1 or LZ4>> | B22: Student Pick-up/ Drop-off
B23: Outdoor Dining
A24: does not show up for LZ4>> | B24: Security for Retail Parking & Pedestrian Hardscape
A25: does not show up for LZ1>> | B25: Security Camera in General Hardscape > 10ft from Bldg

Sheet N. Exist. Cond.
B1: User input | D1: auto calculated | H1: From another Table | L1: From look up table
A3: N. EXISTING CONDITIONS POWER ALLOWANCE (alterations only)
A4: This table includes all existing luminaires being replaced to establish the lighting power allowance per §141.0(b)2Lii, §141.0(b)2Liii or §180.2(b)4Bvb and §180.2(b)4Bvc. Existing luminaires that are remaining or being moved should NOT be included. Outdoor lighting attached to multifamily buildings and controlled from the inside of a dwelling unit are included in Table H. and are not included here. All other multifamily outdoor lighting is included here.
A5: Existing Conditions Wattage:
A6: 01 | B6: 02 | C6: 03 | E6: 04 | F6: 05 | J6: 06 | K6: 07
A7: Name or Item Tag | B7: Complete Luminaire Description | C7: Watts per luminaire1,2 | E7: How Wattage is Determined | F7: # of Luminaires Being Replaced2 | J7: Existing Watts | K7: Field Inspector
K8: Pass | L8: Fail
E9: Dropdown, See below for list. | J9: =C9*F9 -> 0 | K9: o | L9: o
H10: Total Existing Watts : | J10: sum of column 06 (N06)
H11: Allowance per §141.0(b)2L/§180.2(b)4Bv:
A12: * NOTES: Selections with a * require a note in the space below explaining how compliance is achieved.
A13: EX: Photograph of existing luminaire
A14: If the users select options with a *, the Name or Item Tag (uneditable) should show up in Notes section. If users unselect options with a *, the note should dissapear. | B14: This box should work just like the one on the indoor lighting form except the text in the notes box when it's triggered should read "Explain here why item with asterisk complies"
A15: 1 FOOTNOTES: Authority Having Jurisdiction may ask for Luminaire cut sheets to confirm wattage used for compliance per §130.0(c)/§160.5(b).
A16: 2 For linear luminaires, wattage should be indicated as W/lf instead of Watts/luminaire. Total linear feet for the luminaire should be indicated in column 05 instead of number of luminaires.
E17: How Wattage is Determined Dropdown
E19: NA8 Default
E20: Mfr. Spec1
E21: Other*

Sheet O. NRCI
B1: User input | E1: auto calculated | I1: From another Table | M1: From look up table
A3: O. DECLARATION OF REQUIRED CERTIFICATES OF INSTALLATION
A4: Selections have been made based on information provided in this document. If any selections have been changed by the permit applicant, an explanation should be included in Table E. Additional Remarks. These documents must be provided to the building inspector during construction and can be found online .
A5: YES | B5: NO | C5: Form/Title | D5: Field Inspector
D6: Pass | E6: Fail
A7: ● | B7: m | C7: NRCI-LTO-E - Must be submitted for all buildings. | D7: o | E7: o
C10: +

Sheet O. LMCI
B1: User input | E1: auto calculated | I1: From another Table | M1: From look up table
A3: O. DECLARATION OF REQUIRED CERTIFICATES OF INSTALLATION
A4: Selections have been made based on information provided in this document. If any selections have been changed by the permit applicant, an explanation should be included in Table E. Additional Remarks. These documents must be provided to the building inspector during construction and can be found online.
A5: YES | B5: NO | C5: Form/Title | D5: Field Inspector
D6: Pass | E6: Fail
A7: ● | B7: m | C7: LMCI-LTO-E - Must be submitted for all buildings. | D7: o | E7: o

Sheet P. NRCA
B1: User input | F1: auto calculated | J1: From another Table | N1: From look up table
A3: P. DECLARATION OF REQUIRED CERTIFICATES OF ACCEPTANCE
A4: Selections have been made based on information provided in this document. If any selections have been changed by the permit applicant, an explanation should be included in Table E. Additional Remarks. These documents must be provided to the building inspector during construction and must be completed through an Acceptance Test Technician Certification Provider (ATTCP). For more information visit: http://www.energy.ca.gov/title24/attcp/providers.html.
A5: YES | B5: NO | C5: Form/Title | D5: Systems/Spaces to be Field Verified | E5: Field Inspector
E6: Pass | F6: Fail
A7: ● | B7: m | C7: NRCA-LTO-02-A - Must be submitted for all outdoor lighting controls except for alterations where controls area added to < 20 luminaires. | E7: o | F7: o

Sheet Signature
B1: DOCUMENTATION AUTHOR'S DECLARATION STATEMENT
B2: Documentation Author Name: | D2: Documentation Author Signature:
B3: Company: | D3: Signature Date:
B4: Address: | D4: CEA/AEA/ECC Certification Identification (if applicable):
B5: City/State/Zip: | D5: Phone:
B6: RESPONSIBLE PERSON'S DECLARATION STATEMENT I certify the following under penalty of perjury, under the laws of the State of California: 1. The information provided on this Certificate of Compliance is true and correct. 2. I am eligible under Division 3 of the Business and Professions Code to accept responsibility for the building design or system design identified on this Certificate of Compliance (responsible designer) 3. The energy features and performance specifications, materials, components, and manufactured devices for the building design or system design identified on this Certificate of Compliance conform to the requirements of Title 24, Part 1 and Part 6 of the California Code of Regulations. 4. The building design features or system design features identified on this Certificate of Compliance are consistent with the information provided on other applicable compliance documents, worksheets, calculations, plans and specifications submitted to the enforcement agency for approval with this building permit application. 5. I will ensure that a completed signed copy of this Certificate of Compliance shall be made available with the building permit(s) issued for the building, and made available to the enforcement agency for all applicable inspections. I understand that a completed signed copy of this Certificate of Compliance is required to be included with the documentation the builder provides to the building owner at occupancy.
B7: Responsible Designer Name: | D7: Responsible Designer Signature:
B8: Responsible Person Scope
B9: Company: | D9: Date Signed:
B10: Address: | D10: License:
B11: City/State/Zip: | D11: Phone:
B14: Tool Tip:
B15: [d:OnlyUI] The compliance documentation is not complete until the Documentation Author and Responsible Designer fill out and sign the NRCC-LTS form. [d:/OnlyUI]
