Workbook
Name CalcMethod: '[1]NRCC B. Project Scope'!#REF!
Name CalcMethod: #REF!
Name CalcMethod: '[2]B. Project Scope'!#REF!
Name CalcMethod: 'B. Project Scope'!$E$19:$E$22
Name New: '[3]B. Project Scope'!#REF!
Name TEST: '[2]B. Project Scope'!#REF!

Sheet Change Log
A1: Date | B1: Table | C1: Change | D1: Color | E1: Addressed in XSD Schema
A2: 45581 | B2: Footer | C2: Change date in footer | D2: Yellow with red text
A3: 45581 | B3: Signature Block | C3: Add "Responsible Person Scope" field | D3: Yellow with red text
A4: 45581 | B4: Signature Block | C4: Added AEA and replaced "HERS" with "ECC" | D4: Yellow with red text
A5: 45596 | B5: Section B - Column 01 | C5: Added "Altered Lighting System - Parking Garage" | D5: Yellow with red text
A6: 45581 | B6: Section B - Column 02 & 04 | C6: Removed "Tailored" and "Area Category + Tailored" options | D6: Yellow with red text
A7: 45581 | B7: Section B - Column 02 & 04 | C7: Change from "Rated Power Reduction" to "One for One Alteration" | D7: Yellow with red text
A8: 45581 | B8: Section C | C8: Removed Column 04 "Tailored" and renumbered rest of columns | D8: Yellow with red text
A9: 45581 | B9: Section C | C9: Change from "Rated Power Reduction" to "One for One Alteration" | D9: Yellow with red text
A10: 45581 | B10: Section H - Column 06 | C10: Changed from "Manual Area Controls" to "Manual Controls" | D10: Yellow with red text
A11: 45581 | B11: Section H - Column 07 | C11: Revised several dropdown options | D11: Yellow with red text
A12: 45581 | B12: Section H - Column 08 | C12: Vacancy Sensor added to dropdown | D12: Yellow with red text
A13: 45596 | B13: Setion H - Column 09 & 10 | C13: Modified/added to primary and secondary daylight enumerations | D13: Yellow with red text
... A23: 45581 | B23: Section V | C23: NRCA-LTI-03-A changed to "daylight responsive controls." | D23: Yellow with red text
A25: CEC
A26: 45622 | B26: Section H - 07 Multi-Level Dropdown | C26: Change the term from "Enclosed area" to "Space. | D26: See Simon's note
A27: 45622 | B27: Section H - 06 Manual Dropdown | C27: Revised to reflect the 2025 language in §130.1(a) | D27: See Simon's note
A28: 38317 | B28: Section H - | C28: Added/Deleted from "02 Shut-Off Controls (at Bldg)" Dropdown. | D28: See Simon's note
A29: 45623 | B29: Section I - Complete Building or Area Category Primary Function Area Dropdown List | C29: Physical Therapy (Hospitals) should be 0.75, not 0.85, for the 2025 Energy Code. | D29: See Simon's note

Sheet Table Sequence
A1: Label | B1: Table Title | C1: Trigger within: | D1: Note:
A2: Table A | B2: General Information | C2: ALWAYS
A3: Table B | B3: Project Scope | C3: ALWAYS
A4: Table C | B4: Compliance Results | C4: ALWAYS
A5: Table D | B5: Exceptional Conditions | C5: ALWAYS
A6: Table E | B6: Additional Remarks | C6: ALWAYS
A7: Table F | B7: Indoor Lighting Fixture Schedule | C7: ALWAYS except for RPR | D7: this table actually won't show up if table B only includes a Rated Power Reduction compliance method.
A8: Table G | B8: Modular Lighting Systems | C8: Table F
A9: Table H | B9: Indoor Lighting Controls (Not Including PAFs) | C9: If F is triggered, so is H.
A10: Table I | B10: Lighting Power Allowance: Complete Building or Area Category Methods | C10: Table B
A11: Table J | B11: Additional Lighting Allowance: Area Category Method Qualifying System | C11: Table I
A12: Table K | B12: Tailored Method General Lighting Power Allowance | C12: Table B
A13: Table L | B13: Additional Lighting Allowance: Tailored Wall Display | C13: Table K
A14: Table M | B14: Additional Lighting Allowance: Tailored Floor and Task Lighting | C14: Table K
A15: Table N | B15: Additional Lighting Allowance: Tailored Ornamental/ Special Effects | C15: Table K
A16: Table O | B16: Additional Lighting Allowance: Tailored Very Valuable Merchandise | C16: Table K
A17: Table P | B17: Power Adjustment: Lighting Control Credit (PAF) | C17: Table I & Table K
A18: Table Q | B18: Rated Power Reduction Compliance For Alterations | C18: Table B
A19: Table R | B19: 80% Lighting Power For Alterations | C19: Table H
... A24: - | B24: Documentation Author's Declaration Statement | C24: ALWAYS

Sheet Hyperlinks
A1: Label | B1: Tables
A2: §110.9 | B2: Header, H
A3: §110.12(c) | B3: Header | D3: NOT UPDATED FOR 2022, BUT LEFT FOR REFERENCE
A4: §130.0 | B4: Header
A5: §130.0(c) | B5: F
A6: §130.1 | B6: Header
A7: §140.6 | B7: Header, B
A8: §141.0(b)2 | B8: Header, B
A9: §140.6(a) | B9: C, I
A10: §140.6(a)2 | B10: C, P
A11: §140.6(b) | B11: C, I
A12: §140.6(c)1 | B12: C
A13: §140.6(c)2 | B13: C
A14: §140.6(c)3 | B14: C, K
A15: §140.6(c)2G | B15: C
... A32: Table 140.3-D | B32: S

Sheet NRCC Headers
B1: User input | D1: auto calculated | H1: From another Table | K1: From look up table
A3: STATE OF CALIFORNIA
A4: Indoor Lighting
A5: NRCC-LTI-E (Created XX/XX) | I5: CALIFORNIA ENERGY COMMISSION
A6: CERTIFICATE OF COMPLIANCE | K6: NRCC-LTI-E
A7: This document is used to demonstrate compliance with requirements in §110.9, §110.12(c), §130.0, §130.1, §140.6, and §141.0(b)2 for indoor lighting scopes using the prescriptive path for nonresidential and hotel/motel occupancies. It is also used to document compliance with requirements in §160.5, §170.2(e) and §180.2(b)4 for indoor lighting scopes using the prescriptive path for multifamily occupancies. Multifamily includes dormitory and senior living facilities.
A8: Project Name: | I8: Report Page: | K8: Page 1 of ??
A9: Project Address: | I9: Date Prepared:
A12: STATE OF CALIFORNIA
A13: Indoor Lighting
A14: NRCC-LTI-E (Created XX/XX) | I14: CALIFORNIA ENERGY COMMISSION
A15: CERTIFICATE OF COMPLIANCE | K15: NRCC-LTI-E
A16: Project Name: | I16: Report Page: | K16: Page 2 of ??
A17: Project Address: | I17: Date Prepared:

Sheet LMCC Headers
B1: User input | D1: auto calculated | H1: From another Table | K1: From look up table
A3: STATE OF CALIFORNIA
A4: Indoor Lighting
A5: LMCC-LTI-01-E | I5: CALIFORNIA ENERGY COMMISSION
A6: CERTIFICATE OF COMPLIANCE | K6: LMCC-LTI-01-E
A7: This document is used to demonstrate compliance with requirements in §110.9, §110.12(c), §130.0, §130.1, §140.6, and §141.0(b)2 for indoor lighting scopes using the prescriptive path for nonresidential and hotel/motel occupancies in low-rise multifamily mixed-use buildings. It is also used to document compliance with requirements in §160.5, §170.2(e) and §180.2(b)4 for indoor lighting scopes using the prescriptive path for multifamily occupancies. Multifamily includes dormitory and senior living facilities.
A8: Project Name: | I8: Report Page: | K8: Page 1 of ??
A9: Project Address: | I9: Date Prepared:
A12: STATE OF CALIFORNIA
A13: Indoor Lighting
A14: LMCC-LTI-01-E | I14: CALIFORNIA ENERGY COMMISSION
A15: CERTIFICATE OF COMPLIANCE | K15: LMCC-LTI-01-E
A16: Project Name: | I16: Report Page: | K16: Page 2 of ??
A17: Project Address: | I17: Date Prepared:

Sheet NRCC Footers
B1: User input | D1: auto calculated | G1: From another Table | J1: From look up table
A4: Footer for every page:
A6: Registration Number: | E6: Registration Date/Time: | I6: Registration Provider:
E7: Report Version: | I7: Compliance ID:
E8: Schema Version: | I8: Report Generated:
A9: CA Building Energy Efficiency Standards - 2025 Nonresidential Compliance

Sheet LMCC Footers
B1: User input | D1: auto calculated | G1: From another Table | J1: From look up table
A4: Footer for every page:
A6: Registration Number: | E6: Registration Date/Time: | I6: Registration Provider:
E7: Report Version: | I7: Compliance ID:
E8: Schema Version: | I8: Report Generated:
A9: CA Building Energy Efficiency Standards - 2025 Low-rise Multifamily Compliance

Sheet NRCC A. General Info
B1: User input | D1: auto calculated | F1: From another Table | H1: From look up table
A3: A. GENERAL INFORMATION
A4: 01 | B4: Project Location (city) | G4: 04 | H4: Total Conditioned Floor Area (ft²)
A5: 02 | B5: Climate Zone | G5: 05 | H5: Total Unconditioned Floor Area (ft²)
A6: 03 | B6: Occupancy Types Within Project (select all that apply): | G6: 06 | H6: # of Stories (Habitable Above Grade)

Sheet LMCC A. General Info
B1: User input | D1: auto calculated | F1: From another Table | H1: From look up table
A3: A. GENERAL INFORMATION
A4: 01 | B4: Project Location (city) | G4: 04 | H4: Total Conditioned Floor Area (ft²)
A5: 02 | B5: Climate Zone | G5: 05 | H5: Total Unconditioned Floor Area (ft²)
A6: 03 | B6: Occupancy Types Within Project (select all that apply): | G6: 06 | H6: # of Stories (Habitable Above Grade)

Sheet B. Project Scope
B1: User input | D1: auto calculated | F1: From another Table | I1: From look up table
A3: B. PROJECT SCOPE
A4: This table includes any lighting systems that are within the scope of the permit application and are demonstrating compliance using the prescriptive path outlined in §140.6/§170.2(e) or §141.0(b)2/§180.2(b)4 for alterations.
A5: Scope of Work | E5: Conditioned Spaces | G5: Unconditioned Spaces
A6: 01 | E6: 02 | F6: 03 | G6: 04 | I6: 05
A7: My Project Consists of (check all that apply): | E7: Calculation Method | F7: Area (ft²) | G7: Calculation Method | I7: Area (ft²)
B8: New Lighting System
B9: New Lighting System- Parking Garage | E9: only dropdown choice is "Complete Building" | G9: only dropdown choice is "Complete Building"
B11: Altered Lighting System
B12: Altered Lighting System - Parking Garage | E12: Complete Building Or One-For One Alteration | G12: Complete Building or One-For-One Alteration
A14: Total Area of Work (ft2) | E14: =SUM(F8:F11) -> 0 | G14: =SUM(I8:I11) -> 0
A15: ALERT! The One-for-One Luminaire Alteration Rated Power Reduction Method for alterations may only be used for one-for-one luminaire alterations within a building or tenant space of 5,000 ft2 or less per §141.0(b)2Iiii/§180.2(b)4.
E17: Calculation Method | G17: Calculation Method
E18: Complete Building | F18: <<< | G18: Complete Building | I18: <<< Triggers Table F, Table H, and Table I
E19: Area Category | F19: <<< | G19: Area Category | I19: <<< Triggers Table F, Table H, and Table I
E20: Tailored | F20: <<< | G20: Tailored | I20: <<< Triggers Table F, Table H, and Table K
E21: Area Category + Tailored | F21: <<< | G21: Area Category + Tailored | I21: <<< Triggers Table F, Table H, Table I, and Table K
D22: only shows up for alterations >> | E22: Rated Power Reduction One for One Alteration | F22: <<< | G22: Rated Power Reduction One for One Alteration | I22: <<< Triggers Table Q

Sheet C. Compliance 
B1: User input | D1: Auto calculated | G1: From another Table | L1: From look up table
A4: C. COMPLIANCE RESULTS
A5: If any cell on this table says "DOES NOT COMPLY" or "COMPLIES with Exceptional Conditions" refer to Table D. for guidance.
A6: Lighting in conditioned and unconditioned spaces must not be combined for compliance per §140.6(b)1/ §170.2(e). | B6: Allowed Lighting Power per §140.6(b)/§170.2(e) (Watts) | H6: > | I6: AdjustedLighting Power per §140.6(a)/§170.2(e) (Watts) | N6: Compliance Results
B7: 01 | C7: 02 | D7: 03 | E7: 04 | F7: = | G7: 05 04 | I7: 06 05 | J7: 07 06 | K7: = | L7: 08 07 | N7: 09 08
B8: Complete Building §140.6(c)1 | C8: Area Category §140.6(c)2/ §170.2(e)4 | D8: Area Category Additional §140.6(c)2G/ §170.2(e)4Av (+) | E8: Tailored §140.6(c)3/ §170.2(e)4B (+) | G8: Total Allowed (Watts) | I8: Total Designed (Watts) | J8: Adjustments | L8: Total Adjusted (Watts) *Includes Adjustments | N8: 05 Must be >= 08 §140.6/§170.2(e)
J9: PAF Lighting Control Credits §140.6(a)2/ §170.2(e)1B (-)
B10: (See Table I) | C10: (See Table I) | D10: (See Table J) | E10: (See Table K) | I10: (See Table F) | J10: (See Table P)
A11: Conditioned: | B11: ='I. Power Allowance'!G10 -> 0 | C11: ='I. Power Allowance'!G10 -> 0 | D11: ='J. ACM Qualifying System'!D12 -> sum of Total Additional Allowance for whole table | E11: ='K. Tailored Method'!H17 -> #VALUE! | F11: = | G11: =B11+C11+D11+E11+#REF! -> #VALUE! | H11: > | I11: ='F. Lighting Schedule'!M10 -> 0 | J11: ='P. PAFs'!Q13 -> 0 | K11: = | L11: =I11-J11 -> 0 | N11: =IF(G11>=L11, "COMPLIES", "DOES NOT COMPLY") -> #VALUE!
A12: Unconditioned: | B12: ='I. Power Allowance'!G17 -> 0 | C12: ='I. Power Allowance'!G17 -> 0 | D12: ='J. ACM Qualifying System'!D20 -> sum of Total Additional Allowance for whole table | E12: ='K. Tailored Method'!H30 -> #VALUE! | F12: = | G12: =B12+C12+D12+E12 -> #VALUE! | H12: > | I12: ='F. Lighting Schedule'!M17 -> 0 | J12: ='P. PAFs'!Q22 -> 0 | K12: = | L12: =I12-J12 -> 0 | N12: =IF(G12>=L12, "COMPLIES", "DOES NOT COMPLY") -> #VALUE!
A13: Controls Compliance (See Table H for Details) | L13: COMPLIES with Exceptional Conditions or COMPLIES or DOES NOT COMPLY
A14: Rated Power Reduction One-for-One Luminaire Alterations Compliance (See Table Q for Details) | L14: COMPLIES or DOES NOT COMPLY or NOT APPLICABLE

Sheet D. Exceptional Conditions
B1: User input | E1: auto calculated | H1: From another Table | K1: From look up table
A3: D. EXCEPTIONAL CONDITIONS
A4: This table is auto-filled with uneditable comments because of selections made or data entered in tables throughout the form.
A8: The conditioned and/or unconditioned floor area entered in Table A. does not match the total areas entered in Table B or Table I.
A9: Table H. indicates a control requiring a note describing the compliance approach, but no notes have been entered.
A11: Track Lighting has been included in this project, details are provided in Table G.
A12: Track lighting has been indicated on Table F, however Table G has not been completed to calculate the allowance.
A13: User entered Notes in Table H will show up in Table D.
A14: User entered Notes in Table Q will show up in Table D.
A15: Selections made in Table U have been changed by the permit applicant. See Table E. Additional Remarks for permit applicant's explaination.
A16: Selections made in Table V have been changed by the permit applicant. See Table E. Additional Remarks for permit applicant's explaination." should show up in Table D.
A18: Table H. indicates multi-level, daylighting or demand response controls are not required in one or more spaces because the project includes an alteration where the lighting power does not exceed 80% of the allowance from §140.6. However, alteration lighting power documented in Table R. exceeds .8
A19: Table H. indicates multi-level, daylighting or demand response controls are not required in one or more spaces because the project includes an alteration where the lighting power does not exceed 80% of the allowance from §140.6. However, Table R. has not been completed to demonstrate compliance.

Sheet E. Additional Remarks
B1: User input | E1: auto calculated | H1: From another Table | K1: From look up table
A3: E. ADDITIONAL REMARKS
A4: This table includes remarks made by the permit applicant to the Authority Having Jurisdiction.

Sheet F. Lighting Schedule
B1: User input | D1: auto calculated | H1: From another Table | N1: From look up table
A3: F. INDOOR LIGHTING FIXTURE SCHEDULE
A4: This table includes all planned permanent and portable lighting other than dwelling unit/ hotel/ motel room lighting. Multifamily dwelling unit and hotel/motel room lighting is documented in Table T. If using Table T to document lighting in multifamily common use areas providing shared provisions for living, eating, cooking or sanitation, those luminaires are not included here.
A5: Designed Wattage: Conditioned Spaces | Q5: NA8 Default
A6: 01 | B6: 02 | C6: 03 | D6: 04 | E6: 05 | G6: 06 | H6: 07 | L6: 08 | M6: 09 | N6: 10
A7: Name or Item Tag | B7: Complete Luminaire Description | C7: Modular (Track) Fixture | D7: Small Aperture & Color Change1 | E7: Watts per luminaire2 | G7: How Wattage is Determined | H7: Total Number Luminaires | L7: Excluded per §140.6(a)3/ §170.2(e)2C | M7: Design Watts | N7: Field Inspector | Q7: Mfr. Spec¹
N8: Pass | O8: Fail | Q8: Other
C9: ¨ | D9: dropdown | G9: Dropdown | L9: ¨ | M9: =E9*H9 -> 0 | N9: ¨ | O9: ¨
A10: Total Designed Watts CONDITIONED SPACES: | M10: =SUM(M9) -> 0
A12: Designed Wattage: Unconditioned Spaces
A13: 01 | B13: 02 | C13: 03 | D13: 04 | E13: 05 | G13: 06 | H13: 07 | L13: 08 | M13: 09 | N13: 10
A14: Name or Item Tag | B14: Complete Luminaire Description | C14: Modular (Track) Fixture | D14: Small Aperture & Color Change1 | E14: Watts per luminaire2 | G14: How Wattage is Determined | H14: Total Number Luminaires | L14: Excluded per §140.6(a)3/ §170.2(e)2C | M14: Design Watts | N14: Field Inspector
N15: Pass | O15: Fail
C16: ¨ | D16: dropdown | G16: dropdown | L16: ¨ | M16: =E16*H16 -> 0 | N16: ¨ | O16: ¨
A17: Total Designed Watts UNCONDITIONED SPACES: | M17: =SUM(M16) -> 0
A19: ¹ FOOTNOTE: Design Watts for small aperture and color changing luminaires which qualify per §140.6(a)4B/§170.2(e)2D is adjusted to be 75%/80% of their rated wattage. Table F automatically makes this adjustment, the permit applicant should enter full rated wattage in column 05.
A20: 2 Authority Having Jurisdiction may ask for Luminaire cut sheets to confirm wattage used for compliance per §130.0(c)/§160.5(b). Wattage used must be the maximum rated for the luminaire, not the lamp.
G21: How Wattage is Determined
G22: IF column03 = Track: column06 = "See Table G" ELSE: column06 = enum("NA8 Default", Mfr. Spec¹, Other)
D24: Sm. Aperature Dropdown | G24: Wattage Dropdown
D25: Used in Nonres Occupancy | G25: NA8 Default
D26: Used in multifamily occupancy | G26: Mfr Spec1
D27: NA | G27: Other

Sheet G. Modular Lighting Systems
B1: User input | D1: auto calculated | H1: From another Table | M1: From look up table
A4: G. MODULAR LIGHTING SYSTEMS
A5: This table calculates wattage for modular lighting systems/ track lighting fixtures indicated on Table F and transfers the wattage to Table F.
A6: 01 | B6: 02 | D6: 03 | W6: 04
A7: Name or Item Tag | B7: Complete Track Description | D7: Calculation Method per §130.0(c)6 | W7: Track Wattage
A8: autofill from Table F | B8: autofill from Table F | D8: ¨ | E8: i | F8: Installed Luminaires vs Default 30 W/ft | G8: ¨ | H8: ii | I8: Current Limiter 1 | M8: ¨ | N8: iii | O8: Overcurrent Protection Panel2 | R8: ¨ | S8: iv | T8: Power supplied by driver, power supply or transformer1
A9: This shows up if Method (i) is selected above>>> | D9: Number of luminaires in system | G9: x | H9: Rated Watts per luminaire | J9: = | K9: Total Watts | N9: OR | O9: Linear ft of track or busway | Q9: x | R9: Default W/LF | T9: = | U9: Total Watts | W9: =MAX(K10,U10) -> 0
K10: =D10*H10 -> 0 | R10: 30 | U10: =O10*R10 -> 0
A11: This shows up if Method (ii) is selected above>>> | D11: VA of current limiter | W11: =D12 -> 0
A13: This shows up if Method (iii) is selected above>>> | D13: Voltage of branch circuit | N13: x | O13: Sum of Ampere ratings for all devices on panel | W13: =D14*O14 -> 0
A15: This shows up if Method (iv) is selected above>>> | D15: Maximum rated input wattage per manufacturer | W15: =D16 -> 0
A17: 1 FOOTNOTE: For power-over-Ethernet lighting systems, power provided to installed non-lighting devices may be subtracted from the total power rating of the power-over-Ethernet system.
A20: Once the track wattage is calculated in Table G, that value autofills the track "watts per luminaire" in Table F. The Table G options will have to be repeated for each track fixture type user input in Table F.

Sheet H. Lighting Control
B1: User input | E1: auto calculated | I1: From another Table | N1: From look up table
A3: H. INDOOR LIGHTING CONTROLS (Not Including PAFs)
A4: This table includes lighting controls for conditioned and unconditioned spaces. When a control having a * is shown, the notes section of this table provides more detail on how compliance is achieved. The lighting controls section of the Compliance Summary Table on the first page will show "DOES NOT COMPLY" if the notes are left blank. | D4: Building Level Controls
D5: 01 | M5: 02 | X5: 03
D6: Mandatory Demand Response | M6: Shut-off Controls | X6: Field Inspector
D7: §110.12(c) | M7: §130.1(c)/§160.5(b)4C | X7: Pass | Y7: Fail
D8: See dropdown | M8: See Dropdown | X8: ¨ | Y8: ¨
A9: Area Level Controls
A10: 04 | B10: 05 | C10: 06 | F10: 07 | J10: 08 | O10: 09 | S10: 10 | W10: 11 | X10: 12
A11: Area Description | B11: Complete Building or Area Category Primary Function Area | C11: Manual Area Controls §130.1(a)/§160.5(b)4A | F11: Multi-Level Controls §130.1(b)/§160.5(b)4B | J11: Shut-Off Controls §130.1(c)/§160.5(b)4C | O11: Primary/Skylit Daylighting | S11: Secondary Daylighting | W11: Interlocked Systems | X11: Field Inspector
O13: §130.1(d)/§160.5(b)4D | S13: §130.1(d)/§160.5(b)4D | W13: §140.6(a)1/§170.2(e)2A | X13: Pass | Y13: Fail
B14: This dropdown will customize based on whether complete building or area category is chosen in Table B (same as Table I column 02) | C14: See Dropdown | F14: See dropdown | J14: See dropdown | O14: See dropdown | S14: See dropdown | W14: ¨ | X14: ¨ | Y14: ¨
O15: 13
O16: Plan Sheet Showing Daylit Zones:
A20: If the user does not select any * control but does complete at least 1 line on this table, Controls Compliance in Table C. should say "COMPLIES"
D21: 01 Demand Response Dropdown | M21: 02 Shut-Off Controls (at Bldg)
D22: Required: >= 4,000W subject to multilevel | M22: Whole Building Timeswitch
D23: Required: Using as PAF (Table P) | M23: Whole Building EMCS
D24: NA: <4,000W subject to multilevel | M24: See Area/ Space Level Controls (Column 08)
D25: NA: per H&LS
D26: NA: Licensed Healthcare
D27: NA: <= 80% LP (alt only)
C30: 06 Manual Dropdown | F30: 07 Multi-Level Dropdown | J30: 08 Shutoff Dropdown | O30: Primary Daylight | S30: Secondary Daylight
C31: Readily Accessible and located in the same space. | F31: Dimmer | J31: Occ. Sensor | O31: Included | S31: Included
C32: Readily Accessible and located where the lighting or its status can be seen. Auth. Personnel | F32: Multilevel switch | J32: Building Level (Shut-off control requirements are met at the building level) | S32: Primary not required and <85W
C33: Aunniciated | F33: NA: <= 80% LP (alt only) | J33: Partial Off 130.1(c)/ 160.5(b)4C | O33: NA: <= 80% LP (alt only) | S33: NA: <= 80% LP (alt only)
F34: NA: General Ltg <= 0.5 W/SF | J34: Partial On 130.1(c)/160.5(b)4C | O34: NA: Rm < 24sf glazing | S34: NA: Rm < 24sf glazing
F35: NA: Space Enclosed area < 100sf | J35: Countdown timer | O35: NA: Garage < 36sf opening | S35: NA: Garage < 36sf opening
F36: NA: Enclosed area Indoor space w/ only 1 inseparable SSL luminaire | J36: Vacancy Sensor | O36: NA: Skylight shaded | S36: NA: Skylight shaded
F37: NA: Enclosed area w/ 1 luminaire <= 2 lamps | J37: Auto Time Switch | O37: NA: Overhang | S37: NA: Overhang
F38: NA: Restrooms | J38: EMCS | O38: NA: General Ltg < 75 120W | S38: NA: General Ltg < 75 120W
F39: NA: Licensed Healthcare | J39: NA: Licensed Healthcare | O39: NA: Garage General Ltg < 60W | S39: NA: Garage General Ltg < 60W
J40: NA: Elec. equip. rm | O40: NA: Garage daylight adaption zone | S40: NA: Garage daylight adaption zone
J41: NA: 24 hour/365 day | O41: NA: Sidelit retail sales area | S41: NA: Sidelit retail sales area
O42: NA: Not Daylit Zone | S42: NA: Not Daylit Zone

Sheet I. Power Allowance
B1: User input | D1: auto calculated | G1: From another Table | J1: From look up table
A3: I. LIGHTING POWER ALLOWANCE: COMPLETE BUILDING OR AREA CATEGORY METHODS
A4: Each area complying using the Complete Building or Area Category Methods per §140.6(b) are included in this table. Column 06 indicates if additional lighting power allowances per §140.6(c) or adjustments per §140.6(a) are being used.
A5: Conditioned Spaces
A6: 01 | D6: 02 | E6: 03 | F6: 04 | G6: 05 | H6: 06
A7: Area Description | D7: Complete Building or Area Category Primary Function Area | E7: Allowed Density (W/ft2) | F7: Area (ft²) | G7: Allowed Wattage (watts) | H7: Additional Allowance/ Adjustment
H8: Area Category | I8: PAF
D9: This dropdown will customize based on whether complete building or area category is chosen in Table B (same as Table I column 02) | E9: From Table below | G9: calculated as LPD x 04 (LPD is determined based on 02 selection) | H9: Triggers Table J | I9: Triggers Table P
E10: TOTALS: | F10: =SUM(F9:F9) -> 0 | G10: =SUM(G9:G9) -> 0 | H10: See Tables J or P for detail
H11: Duplicate Row | I11: Add Row
A12: Unconditioned Spaces
A13: 01 | D13: 02 | E13: 03 | F13: 04 | G13: 05 | H13: 06
A14: Area Description | D14: Complete Building or Area Category Primary Function Area | E14: Allowed Density (W/ft2) | F14: Area (ft²) | G14: Allowed Wattage (watts) | H14: Additional Allowance/ Adjustment
H15: Area Category | I15: PAF
D16: This dropdown will customize based on whether complete building or area category is chosen in Table B (same as Table I column 02) | E16: From Table below | G16: calculated as LPD x 04 (LPD is determined based on 02 selection) | H16: Triggers Table J | I16: Triggers Table P
E17: TOTALS: | F17: =SUM(F16:F16) -> 0 | G17: =SUM(G16:G16) -> 0 | H17: See Tables J or P for detail
H18: Duplicate Row | I18: Add Row | X18: This table is for NONRESIDENTIAL | AK18: This table is for MF COMMON AREAS
C20: Complete Building or Area Category Primary Function Area Dropdown List | G20: LPD
C21: if(Calculation Method in Table B = "Complete Building"): | G21: if (Calculation Method in Table B = "Complete Building"):
C23: Assembly Building | G23: 0.65
C24: "Financial Center Building" | G24: 0.65
C25: "Grocery Store Building" | G25: 0.90
C26: Gymnasium Building | G26: 0.60
C27: Healthcare Facility | G27: 0.90
C28: Industrial Manufacturing Building | G28: 0.60
C29: "Library Building" | G29: 0.70
C30: Motion Picture Theater Building | G30: 0.60
C31: Museum Building | G31: 0.65
C32: "Office Building" | G32: 0.60 | AW32: <<< different than NR
C33: "Parking Garage Building" | G33: 0.13 | AW33: <<< different than NR
C34: Performing Arts Theater Building | G34: 0.75
C35: "Religious Facility Building" | G35: 0.70
C36: "Restaurant Building" | G36: 0.65
C37: Retail Store Building | G37: 0.90
C38: "School Building" | G38: 0.60
C39: Sports Area Building | G39: 0.75
C40: "All Other Building" | G40: 0.40
C41: else if (Calculation Method in Table B = "Area Category" or Calculation Method in Table B = "Area Category + Tailored"):
C42: Audience Seating Area | G42: 0.50
C43: "Auditorium" | G43: 0.70
...

Sheet J. ACM Qualifying System
C1: User input | E1: auto calculated | H1: From another Table | K1: From look up table
B3: J. ADDITIONAL LIGHTING ALLOWANCE: AREA CATEGORY METHOD QUALIFYING LIGHTING SYSTEM
B4: All areas indicated in Table I as using an additional allowance using the Area Category Method have been included in this table to calculate the additional allowance per Table140.6-C /170.2-M.
B5: Conditioned Spaces
B6: 01 | C6: 02 | D6: 03 | E6: 04 | F6: 05 | G6: 06 | H6: 07 | I6: 08 | J6: 09 | K6: 10
B7: Area Description | C7: Primary Function Area | D7: Applicable Qualifying Lighting System from Table 140.6-C | E7: Allowed Density (W/ft²) or (W/lf) | F7: Ltg Area, Length or ATM/ Mirror (ft², lf or #) | G7: Extra Allowance (Watts) | H7: Luminaire Name or Item Tag | I7: Watts per Luminaire | J7: Number of Luminaires | K7: Total Design Watts
B8: Auto fills from Tbl I. | C8: Auto fills from Tbl I. | D8: Dropdown (See below). Customize based on Function Area in 02 | E8: autofilled by dropdown (see below for values) | G8: calculated as 04x05 | H8: drop down from Table F | I8: Autofill from Table F based on 07 | K8: calculated as 08x09
B9: Total Design Watts: | C9: Calculated Allowance (Watts): | D9: Total Additional Allowance for this area:
B10: sum of column 10 for space | C10: sum of column 06 for space | D10: autofill Total Design Watts or Calculated Allowance, whichever is less
B11: 11
B12: Total Additional Allowance (Watts) CONDITIONED SPACES: | D12: sum of Total Additional Allowance for whole table
B13: Unconditioned Spaces
B14: 01 | C14: 02 | D14: 03 | E14: 04 | F14: 05 | G14: 06 | H14: 07 | I14: 08 | J14: 09 | K14: 10
B15: Area Description | C15: Primary Function Area | D15: Applicable Qualifying Lighting System from Table 140.6-C | E15: Allowed Density (W/ft²) or (W/lf) | F15: Ltg Area, Length or ATM/ Mirror (ft², lf or #) | G15: Extra Allowance (Watts) | H15: Luminaire Name or Item Tag | I15: Watts per Luminaire | J15: Number of Luminaires | K15: Total Design Watts
B16: Auto fills from Tbl I. | C16: Auto fills from Tbl I. | D16: Dropdown (See below). Customize based on Function Area in 02 | E16: autofilled by dropdown (see below for values) | G16: calculated as 04x05 | H16: drop down from Table F | I16: Autofill from Table F based on 07 | K16: calculated as 08x09
B17: Total Design Watts: | C17: Calculated Allowance (Watts): | D17: Total Additional Allowance for this area:
B18: sum of column 10 for space | C18: sum of column 06 for space | D18: autofill Total Design Watts or Calculated Allowance, whichever is less
B19: 11
B20: Total Additional Allowance (Watts) UNCONDITIONED SPACES: | D20: sum of Total Additional Allowance for whole table
B22: Add Footnote button to show up IF the primary function area is either "Retail Merchandise Sales, Wholesale Showroom" OR "Grocery Sales".
B23: Pressing this button essentially duplicates the space in this table (but leaves columns 03-10 uncompleted for user to complete)- see pic below.
B26: Allowed Density For Column 04 Autofill
B27: Decorative/ Display A | C27: 0.15
B28: Decorative/ Display B | C28: 0.2
B29: Decorative/ Display C | C29: 0.25
B30: Decorative/ Display D | C30: 0.3
B31: Decorative/ Display E | C31: 0.35
B32: Decorative/ Display F | C32: 0.45
B33: Detailed Task A | C33: 0.20
B34: Detailed Task B | C34: 0.3
B35: Detailed Task C | C35: 0.35
B36: Chalk/ Whiteboard | C36: 7 | D36: 03 Dropdown
B37: Precision Work | C37: 0.70 | D37: Decorative/ Display F
B38: Portable Office | C38: 0.20
B39: ATM/ Ticket Machine | C39: see note for column 06 | D39: 03 Dropdown
B40: Specialized Task | C40: 0.35 | D40: Detailed Task A
B41: Mirror- Externally Lit | C41: 40
B42: Mirror- Internally Lit | C42: 120 | D42: 03 Dropdown
B43: Tunable White | C43: 0.10 | D43: Decorative/ Display C
B44: Videoconferencing | C44: 1.0
...

Sheet K. Tailored Method
B1: User input | D1: auto calculated | G1: From another Table | J1: From look up table
A2: DELETE TAILORED LIGHTING SECTIONS FOR 2025
A4: K. TAILORED METHOD GENERAL LIGHTING POWER ALLOWANCE
A5: This table includes areas using the Tailored Method per §140.6(c)3/§170.2(e)4B. If additional Tailored Method "use it or lose it" allowances are used it is also indicated. Lighting that qualifies for one of the additional allowances shall not qualify for another additional allowance.
A6: Conditioned Spaces
A7: General Lighting Power Allowance | B7: Additional "Use it or lose it" Allowances | F7: 01
B8: ¨ Wall Display Lighting | C8: ¨ Floor Display & Task Lighting | D8: ¨ Decorative & Special Effects | E8: ¨ Very Valuable Merchandise | F8: Total Allowed Watts using Tailored Method
A9: Table K (below) | B9: Table L | C9: Table M | D9: Table N | E9: Table O | F9: =SUM(A10:E10) -> #VALUE!
A10: =H17 -> #VALUE! | B10: ='L. Tailored Wall Display'!K12 -> 0 | C10: ='M. Tailored Task Lighting'!K12 -> 0 | D10: ='N. Tailored Decorative'!I12 -> #VALUE! | E10: ='O. Very Valuable'!G17:H17 -> #VALUE!
A11: Calculated General Lighting Power Allowance
A12: 02 | B12: 03 | D12: 04 | E12: 05 | F12: 06 | G12: 07 | H12: 08 | I12: 09
A13: Area Description | B13: Primary Function Area per Table 140.6-D/ 170.2-N | D13: Illuminance Value (LUX) | E13: Room Configuration | F13: Allowed Density (W/ft²) | G13: Area (ft²) | H13: Extra Allowance (Watts) | I13: Power Adjustment (See Table P)
B14: dropdown | D14: autofilled by 03 dropdown | F14: This value will be determined based on illuminance value and room cavity ratio | H14: =F14*G14 -> #VALUE! | I14: ¨ PAF
A15: These rows show up if Room Configuration is selected above>>> | B15: IF column 05 = Rectangular: "Room Length (ft)" ELSE IF column 05 = Non-Rectangular: "Not Applicable" | C15: IF column 05 = Rectangular: "Room Width (ft)" ELSE IF column 05 = Non-Rectangular: "Perimeter (ft)" | D15: Room Height (ft) | E15: Room Cavity Ratio (RCR)
E16: IF 05="Rectangular" RCR = (5*Height*(Length+Width))/(Length*Width) ELSE: RCR = 2.5*Height*Width/07
A17: Total General Power Allowance (Watts) CONDITIONED SPACES: | H17: =SUM(H14) -> #VALUE!
A19: Unconditioned Spaces
A20: General Lighting Power Allowance | B20: Additional "Use it or lose it" Allowances | F20: 01
B21: ¨ Wall Display Lighting | C21: ¨ Floor Display & Task Lighting | D21: ¨ Decorative & Special Effects | E21: ¨ Very Valuable Merchandise | F21: Total Allowed Watts using Tailored Method
A22: Table L (below) | B22: Table L | C22: Table M | D22: Table N | E22: Table O | F22: =SUM(A23:E23) -> #VALUE!
A23: =H30 -> #VALUE! | B23: ='L. Tailored Wall Display'!K21 -> 0 | C23: ='M. Tailored Task Lighting'!K21 -> 0 | D23: ='N. Tailored Decorative'!I21 -> #VALUE! | E23: ='O. Very Valuable'!G30:H30 -> #VALUE!
A24: Calculated General Lighting Power Allowance
A25: 02 | B25: 03 | D25: 04 | E25: 05 | F25: 06 | G25: 07 | H25: 08 | I25: 09
A26: Area Description | B26: Primary Function Area per Table 140.6-D/ 170.2-N | D26: Illuminance Value (LUX) | E26: Room Configuration | F26: Allowed Density (W/ft²) | G26: Area (ft²) | H26: Extra Allowance (Watts) | I26: Power Adjustment (See Table P)
B27: dropdown | D27: autofilled by 03 dropdown | F27: This value will be determined based on illuminance value and room cavity ratio | H27: =F27*G27 -> #VALUE! | I27: ¨ PAF
A28: These rows show up if Room Configuration is selected above>>> | B28: IF column 05 = Rectangular: "Room Length (ft)" ELSE IF column 05 = Non-Rectangular: "Not Applicable" | C28: IF column 05 = Rectangular: "Room Width (ft)" ELSE IF column 05 = Non-Rectangular: "Perimeter (ft)" | D28: Room Height (ft) | E28: Room Cavity Ratio (RCR)
E29: IF 05="Rectangular" RCR = (5*Height*(Length+Width))/(Length*Width) ELSE: RCR = 2.5*Height*Width/07
A30: Total General Power Allowance (Watts) UNCONDITIONED SPACES: | H30: =SUM(H27) -> #VALUE!
R32: This is for NONRESIDENTIAL
E34: This table is for NONRESIDENTIAL
B35: dropdown
B36: Auditorium Area
B37: Convention Area
B38: Conference Area
B39: Multifamily Conference Area
B40: Multipurpose Area
B41: Multifamily Multipurpose Area
B42: Meeting Center Area
B43: Multifamily Meeting Center Area
B44: Dining Areas
...

Sheet L. Tailored Wall Display
B1: User input | D1: auto calculated | F1: From another Table | I1: From look up table
A2: DELETE TAILORED LIGHTING SECTIONS FOR 2025
A4: L. ADDITIONAL LIGHTING ALLOWANCE: TAILORED WALL DISPLAY
A5: Conditioned Spaces
A6: 01 | B6: 02 | C6: 03 | D6: 04 | E6: 05 | F6: 06 | G6: 07 | H6: 08 | I6: 09 | J6: 10 | K6: 11
A7: Area Description | B7: CALCULATED ALLOWANCE (Watts) | E7: DESIGN WATTS | K7: Additional Allowance (Watts)
B8: Wall Display Length (lf) | C8: Wall Display Density (W/lf) | D8: Extra Allowance (Watts) | E8: Luminaire Name or Item Tag | F8: Mounting Height (ft) | G8: Mounting Height Factor | H8: Watts per Luminaire | I8: # of Luminaires | J8: Total Design Watts
A9: Dropdown from Tbl K. | C9: Autofill based on Primary Function (in Table K) of the area | D9: =B9*C9 -> #VALUE! | E9: Drop down from Table F | G9: i | H9: Autofill from Table F based on 05 | J9: =H9*I9 -> #VALUE!
A10: Total Design Watts for this Area: | J10: =SUM(J9) -> #VALUE!
J11: Add Luminaires | K11: Remove Last
A12: Total Additional Allowance (Watts) CONDITIONED SPACES: | K12: =SUM(K10) -> 0
J13: Add Row | K13: Remove Last
A14: Unconditioned Spaces
A15: 01 | B15: 02 | C15: 03 | D15: 04 | E15: 05 | F15: 06 | G15: 07 | H15: 08 | I15: 09 | J15: 10 | K15: 11
A16: Area Description | B16: CALCULATED ALLOWANCE (Watts) | E16: DESIGN WATTS | K16: Additional Allowance (Watts)
B17: Wall Display Length (lf) | C17: Wall Display Density (W/lf) | D17: Extra Allowance (Watts) | E17: Luminaire Name or Item Tag | F17: Mounting Height (ft) | G17: Mounting Height Factor | H17: Watts per Luminaire | I17: # of Luminaires | J17: Total Design Watts
A18: Dropdown from Tbl K. | C18: Autofill based on Primary Function (in Table K) of the area | D18: =B18*C18 -> #VALUE! | E18: Drop down from Table F | G18: if (col06 == "≥ 16 feet"): "0.77"; else if (col06 == "12 to 16 feet"): "0.87"; else: "1"; | H18: Autofill from Table F based on 05 | J18: =H18*I18 -> #VALUE!
A19: Total Design Watts for this Area: | J19: =SUM(J18) -> #VALUE!
J20: Add Luminaires | K20: Remove Last
A21: Total Additional Allowance (Watts) UNCONDITIONED SPACES: | K21: =SUM(K19) -> 0
J22: Add Row | K22: Remove Last
L35: This table is for NONRESIDENTIAL
L52: This table is for MF COMMON AREAS
B70: This table is for MF COMMON AREAS
F86: ^^^
F87: Lobby value not same as NR

Sheet M. Tailored Task Lighting
B1: User input | D1: auto calculated | F1: From another Table | I1: From look up table
A2: DELETE TAILORED LIGHTING SECTIONS FOR 2025
A4: M. ADDITIONAL LIGHTING ALLOWANCE: TAILORED FLOOR AND TASK LIGHTING
A5: Conditioned Spaces
A6: 01 | B6: 02 | C6: 03 | D6: 04 | E6: 05 | F6: 06 | G6: 07 | H6: 08 | I6: 09 | J6: 10 | K6: 11
A7: Area Description | B7: CALCULATED ALLOWANCE (Watts) | E7: DESIGN WATTS | K7: Additional Allowance (Watts)
B8: Area (ft²) | C8: Allowed Density (W/ft²) | D8: Extra Allowance (Watts) | E8: Luminaire Name or Item Tag | F8: Mounting Height (ft) | G8: Mounting Height Factor | H8: Watts per Luminaire | I8: # of Luminaires | J8: Total Design Watts
A9: Dropdown from Tbl K. | C9: Autofill based on Primary Function (in Table K) of the area | D9: =B9*C9 -> #VALUE! | E9: Drop down from Table F | F9: See dropdown | H9: Autofill from Table F based on 05 | J9: =H9*I9 -> #VALUE!
A10: Total Design Watts for this Area: | J10: =SUM(J9) -> #VALUE!
J11: Add Luminaires | K11: Remove Last
A12: Total Additional Allowance (Watts) CONDITIONED SPACES: | K12: =SUM(K10) -> 0
J13: Add Row | K13: Remove Last
A14: Unconditioned Spaces
A15: 01 | B15: 02 | C15: 03 | D15: 04 | E15: 05 | F15: 06 | G15: 07 | H15: 08 | I15: 09 | J15: 10 | K15: 11
A16: Area Description | B16: CALCULATED ALLOWANCE (Watts) | E16: DESIGN WATTS | K16: Additional Allowance (Watts)
B17: Area (ft²) | C17: Allowed Density (W/ft²) | D17: Extra Allowance (Watts) | E17: Luminaire Name or Item Tag | F17: Mounting Height (ft) | G17: Mounting Height Factor | H17: Watts per Luminaire | I17: # of Luminaires | J17: Total Design Watts
A18: Dropdown from Tbl K. | C18: Autofill based on Primary Function (in Table K) of the area | D18: =B9*C9 -> #VALUE! | E18: Drop down from Table F | F18: See dropdown | H18: Autofill from Table F based on 05 | J18: =H18*I18 -> #VALUE!
A19: Total Design Watts for this Area: | J19: =SUM(J18) -> #VALUE!
J20: Add Luminaires | K20: Remove Last
A21: Total Additional Allowance (Watts) UNCONDITIONED SPACES: | K21: =SUM(K19) -> 0
J22: Add Row | K22: Remove Last
F24: Mounting Height Dropdown
F25: < 10'7"
F26: 10'7"-14'
F27: > 14' - 18'
F28: > 18'
B37: This table is for NONRES
B81: This table is for MF COMMON AREAS
G98: ^^None of these are same as NR

Sheet N. Tailored Decorative
B1: User input | D1: auto calculated | F1: From another Table | I1: From look up table
A2: DELETE TAILORED LIGHTING SECTIONS FOR 2025
A4: N. ADDITIONAL LIGHTING ALLOWANCE: TAILORED DECORATIVE/SPECIAL EFFECTS
A5: Conditioned Spaces
A6: 01 | B6: 02 | C6: 03 | D6: 04 | E6: 05 | F6: 06 | G6: 07 | H6: 08 | I6: 09
A7: Area Description | B7: CALCULATED ALLOWANCE (Watts) | E7: DESIGN WATTS | I7: Additional Allowance (Watts)
B8: Area (ft²) | C8: Allowed Density (W/ft²) | D8: Extra Allowance (Watts) | E8: Luminaire Name or Item Tag | F8: Watts per Luminaire | G8: # of Luminaires | H8: Total Design Watts
A9: Dropdown from Tbl K. | C9: Autofill based on Primary Function (in Table K) of the area | D9: =B9*C9 -> #VALUE! | E9: Drop down from Table F | F9: Autofill from Table F based on 05 | H9: =F9*G9 -> #VALUE! | K9: This Table is for NONRES
A10: Total Design Watts for this Area: | H10: =SUM(H9) -> #VALUE! | I10: =MIN(D9,H10) -> #VALUE!
H11: Add Luminaires | I11: Remove Last
A12: Total Additional Allowance (Watts) CONDITIONED SPACES: | I12: =SUM(I10) -> #VALUE!
H13: Add Row | I13: Remove Last
A14: Unconditioned Spaces
A15: 01 | B15: 02 | C15: 03 | D15: 04 | E15: 05 | F15: 06 | G15: 07 | H15: 08 | I15: 09
A16: Area Description | B16: CALCULATED ALLOWANCE (Watts) | E16: DESIGN WATTS | I16: Additional Allowance (Watts)
B17: Area (ft²) | C17: Allowed Density (W/ft²) | D17: Extra Allowance (Watts) | E17: Luminaire Name or Item Tag | F17: Watts per Luminaire | G17: # of Luminaires | H17: Total Design Watts
A18: Dropdown from Tbl K. | C18: Autofill based on Primary Function (in Table K) of the area | D18: =B18*C18 -> #VALUE! | E18: Drop down from Table F | F18: Autofill from Table F based on 05 | H18: =F18*G18 -> #VALUE!
A19: Total Design Watts for this Area: | H19: =SUM(H18) -> #VALUE! | I19: =MIN(D18,H19) -> #VALUE!
H20: Add Luminaires | I20: Remove Last
A21: Total Additional Allowance (Watts) UNCONDITIONED SPACES: | I21: =SUM(I19) -> #VALUE!
H22: Add Row | I22: Remove Last
K48: This table is for MF COMMON AREAS

Sheet O. Very Valuable
B1: User input | D1: auto calculated | F1: From another Table | I1: From look up table
A2: DELETE TAILORED LIGHTING SECTIONS FOR 2025
A4: O. ADDITIONAL LIGHTING ALLOWANCE: TAILORED VERY VALUABLE MERCHANDISE
A5: This category includes case lighting in retail merchandise sales, museums, and religious settings, where lighting of small art objects, artifacts, or valuable collections is required. The display case shall contain jewelry, coins, fine china, fine crystal, precious stones, silver, small art objects or artifacts, and/or valuable collections the display of which involves customer inspection of very fine detail from outside of a locked case. Lighting in this category must comply with the applicable requirements in §140.6(c)3J/§170.2(e)4B.
A6: Conditioned Spaces
A7: 01 | B7: 02 | C7: 03 | D7: 04 | E7: 05 | F7: 06 | G7: 07 | H7: 08
A8: Area Description | B8: Description of Display Case | C8: QUALIFYING FLOOR AREA | F8: QUALIFYING DISPLAY CASE AREA
C9: Area (ft2) | D9: Allowed Density (W/ft²) | E9: Extra Allowance (Watts) | F9: Area of Display Case (ft2) | G9: Allowed Density (W/ft²) | H9: Extra Allowance (Watts)
A10: Dropdown from Tbl K. | D10: 0.5 | E10: =C10*D10 -> 0 | G10: 7 | H10: =F10*G10 -> 0
C11: 09 | D11: 10 | E11: 11 | F11: 12 | G11: 13
C12: DESIGN WATTS | G12: Additional Allowance (Watts)
C13: Luminaire Name or Item Tag | D13: Watts per Luminaire | E13: # of Luminaires | F13: Total Design Watts
C14: pull down from Table F. | D14: auto fill from Table F | F14: =D14*E14 -> #VALUE!
A15: Total Design Watts for this Area: | F15: =SUM(F14) -> #VALUE! | G15: =MIN(E10,H10,F15) -> #VALUE!
G16: Add Luminaire | H16: Remove Last
A17: Total Additional Allowance (Watts) CONDITIONED SPACES: | G17: =SUM(G15) -> #VALUE!
G18: Add Row | H18: Remove Last
A19: Unconditioned Spaces
A20: 01 | B20: 02 | C20: 03 | D20: 04 | E20: 05 | F20: 06 | G20: 07 | H20: 08
A21: Area Description | B21: Description of Display Case | C21: QUALIFYING FLOOR AREA | F21: QUALIFYING DISPLAY CASE AREA
C22: Area (ft2) | D22: Allowed Density (W/ft²) | E22: Extra Allowance (Watts) | F22: Area of Display Case (ft2) | G22: Allowed Density (W/ft²) | H22: Extra Allowance (Watts)
A23: Dropdown from Tbl K. | D23: 0.5 | E23: =C23*D23 -> 0 | G23: 7 | H23: =F23*G23 -> 0
C24: 09 | D24: 10 | E24: 11 | F24: 12 | G24: 13
C25: DESIGN WATTS | G25: Additional Allowance (Watts)
C26: Luminaire Name or Item Tag | D26: Watts per Luminaire | E26: # of Luminaires | F26: Total Design Watts
C27: pull down from Table F. | D27: auto fill from Table F | F27: =D27*E27 -> #VALUE!
A28: Total Design Watts for this Area: | F28: =SUM(F27) -> #VALUE! | G28: =MIN(E23,H23,F28) -> #VALUE!
G29: Add Luminaire | H29: Remove Last
A30: Total Additional Allowance (Watts) UNCONDITIONED SPACES: | G30: =SUM(G28) -> #VALUE!
G31: Add Row | H31: Remove Last

Sheet P. PAFs
B1: User input | E1: auto calculated | M1: From another Table | P1: From look up table
B3: P. POWER ADJUSTMENT: LIGHTING CONTROL CREDIT (POWER ADJUSTMENT FACTOR (PAF))
B4: This table includes all areas indicated in Table I or Table K as using a PAF credit described in §140.6(a)2/ §170.2(e)2B.
B5: Conditioned Spaces
B6: 01 | C6: 02 | M6: 03 | N6: 04 | O6: 05 | P6: 06 | Q6: 07
B7: Area Description | C7: PAF per §140.6(a)2/§170.2(e)2B1 (*Can be used in conjunction with other PAF'S) | M7: Luminaires Controlled for PAF Credit | Q7: Additional Control Credit Allowance (Watts)
C8: 1 | D8: 2A | E8: 2B 3 | G8: 3A 4A* | H8: 3B 4B* | I8: 4 5* | J8: 5 6* | K8: 6 7* | L8: 7 8* | M8: Luminaire Name or Item Tag | N8: Watts per Luminaire | O8: Number of Luminaires | P8: Lighting Controlled (Watts)
C9: Pick up to one | G9: Pick up to one | J9: Pick up to one2
B10: autofill from Table I. or Table K. | M10: pull down from Table F. | N10: auto fill from Table F based on 03 selection | P10: =N10*O10 -> #VALUE! | Q10: PAF x col06
O11: Add Luminaire | Q11: Remove Last
B12: 08 | L12: 09
B13: o | C13: All spaces applying PAF 5, 6, or 7 include a daylight design meeting requirements in §140.3(d). See Table S. | L13: Total Power Adjustment (Watts) CONDITIONED SPACES: | Q13: =SUM(Q10) -> 0
B14: Unconditioned Spaces
B15: 01 | C15: 02 | M15: 03 | N15: 04 | O15: 05 | P15: 06 | Q15: 07
B16: Area Description | C16: PAF per §140.6(a)2/§170.2(e)2B1 (*Can be used in conjunction with other PAF'S) | M16: Luminaires Controlled for PAF Credit | Q16: Additional Control Credit Allowance (Watts)
C17: 1 | D17: 2A | E17: 2B 3 | G17: 3A 4A* | H17: 3B 4B* | I17: 4 5* | J17: 5 6* | K17: 6 7* | L17: 7 8* | M17: Luminaire Name or Item Tag | N17: Watts per Luminaire | O17: Number of Luminaires | P17: Lighting Controlled (Watts)
C18: Pick up to one | G18: Pick up to one | J18: Pick up to one2
B19: autofill from Table I. or Table K. | M19: pull down from Table F. | N19: auto fill from Table F based on 03 selection | P19: =N19*O19 -> #VALUE! | Q19: PAF x col06
O20: Add Luminaire | Q20: Remove Last
B21: 08 | K21: 09
B22: o | C22: All spaces applying PAF 5, 6, or 7 include a daylight design meeting requirements in §140.3(d). See Table S. | K22: Total Power Adjustments (Watts) UNCONDITIONED SPACES: | Q22: =SUM(Q19) -> 0
B23: 1 FOOTNOTES: PAFs outlined in Table 140.6-A/170.2-L include 1) Daylight continuous dimming plus OFF; 2A) Occupant sensors in offices with one sensor per < 125 ft2; 2B 3) Occupant sensors in offices with one sensor per 126 - 250 ft2; 3A 4A) Institutional tuning, non-daylit areas; 3B 4B) Institutional tuning, daylit areas; 4 5) Demand response; 5 6) Clerestory fenestration; 6 7) Horizontal slats; 7 8) Light shelves.
B24: 2 Luminaires that qualify for PAF 5, 6, or 7 can be used in conjunction with PAF 1.
C26: PAF Calculation
C27: if PAF1 is checked: PAF += 0.10 if PAF2A is checked: PAF += 0.30 if PAF2B 3 is checked: PAF += 0.20 if PAF3A 4Ais checked: PAF += 0.10 if PAF3B 4B is checked: PAF += 0.05 if PAF4 5 is checked: PAF += 0.05 if PAF5 6 is checked: PAF +=0.05 if PAF6 7 is checked: PAF +=0.05 if PAF7 8 is checked: PAF +=0.10

Sheet Q. Rated Pwr
C1: User input | E1: auto calculated | K1: From another Table | N1: From look up table
B3: Q. RATED POWER REDUCTION COMPLIANCE FOR ONE-FOR-ONE LUMINAIRE ALTERATIONS
B4: Indoor lighting alterations complying prescriptively with §141.0(b)2I(iii)/§180.2(b)4biv are documented in this table. Any control options having a * will include a note in the Notes section of this table detailing how compliance is achieved, otherwise the compliance status in Table C will say "DOES NOT COMPLY".
B5: 01 | C5: ¨ | D5: Alteration scope includes a one-for-one luminaire alteration within a building or tenant space of 5,000 ft2 or less per §141.0(b)2I(iii)/§180.2(b)4biv.
B6: 02 | C6: ¨ | D6: At least one complete floor or complete tenant space includes a one-for-one luminaire alteration of 50 or less luminaires, per annum. These spaces do not need to comply with Part 6 requirements and therefore do not need to be included in tables below per Exception 6 to §141.0(b)2I/§180.2(b)4biv. | I6: Applicable Spaces | K6: OR | L6: ¨ | M6: Exception 6 applies to all spaces within the permit application
B8: Fixture Schedule (Incude all luminaires being altered in the project)
B9: 03 | C9: 04 | D9: 05 | E9: 06 | F9: 07 | G9: 08 | H9: 09 | I9: 10 | J9: 11 | K9: 12 | L9: 13 | M9: 14
B10: Pre-alteration Luminaire Information | H10: Post-alteration Luminaire Information
B11: Name or Item Tag | C11: Complete Luminaire Description | D11: Watts per luminaire1 | E11: How Wattage is Determined | F11: Total number of Luminaires | G11: Total Watts | H11: Name or Item Tag | I11: Complete Luminaire Description | J11: Watts per luminaire1 | K11: How Wattage is Determined | L11: Total number of Luminaires | M11: Total Watts
E12: see dropdown | G12: =D12*F12 -> 0 | L12: =F12 -> 0 | M12: =J12*L12 -> 0
B14: =(G14-M14)/G14 -> #VALUE! | C14: Percent Power Reduction2 | E14: Total Pre-alteration Wattage | G14: sum of column 08 | H14: Total Post-alteration Wattage | M14: sum of column 14
B15: 1 FOOTNOTE: Authority Having Jurisdiction may ask for Luminaire cut sheets to confirm wattage used for compliance per §130.0(c)/§160.5(b)1
B16: 2 Must be at least 40% to comply with §141.0(b)2I(iii)/§180.2(b)4biv
B17: Mandatory Controls
B18: 15 | D18: 16 | F18: 17 | H18: 18 | J18: 19
B19: Area Description | D19: Primary Function Area | F19: Manual Area Controls §130.1(a)/§160.5(b)4A | H19: Shut-Off Controls §130.1(c)/§160.5(b)4C | J19: * NOTES: Controls with a * require a note in the space below explaining how compliance is achieved
D20: See dropdown | F20: See dropdown | H20: See dropdown
E23: How Wattage Determined
E24: NA8 Default
E25: Mfr. Spec1
E26: Other
D28: Function Area Dropdown | F28: Area Controls Dropdown | H28: Shutoff Controls Dropdown
D29: Use Area Category List | F29: Readily Accessible | H29: Whole Building: Auto Time Switch
F30: Authorized Personnel | H30: Whole Building: EMCS
F31: Annunciated * | H31: Whole Building: Occ Sensor
H32: Occ Sensor
H33: Partial Off 130.1(c)/ 160.5(b)4C *
H34: Partial On 130.1(c)/160.5(b)4C *
H35: Auto Time Switch
H36: EMCS
H37: Countdown timer
H38: Vacancy Sensor
H39: NA: Licensed Healthcare
H40: NA: Elec. equip. rm
H41: NA: 24 hour/365 day

Sheet R. 80% Pwr Reduction
C1: User input | E1: auto calculated | G1: From another Table | J1: From look up table
A3: R. 80% LIGHTING POWER FOR ALTERATIONS- CONTROLS EXCEPTIONS
A4: Indoor lighting alteration spaces complying prescriptively with §141.0(b)2I(ii)/§180.2(b)4Bivb are included in this table to document the power reduction. If the Percent of Indoor Lighting Power Allowance exceeds 80%, the compliance status in Table C for Controls will say "DOES NOT COMPLY".
A5: 01 | B5: 02 | C5: 03 | D5: 04 | E5: 05 | F5: 06 | G5: 07 | H5: 08 | I5: 09
A6: Area Description | B6: Complete Building or Area Category Primary Function Area | C6: CALCULATED ALLOWANCE (Watts) | F6: DESIGN WATTS
C7: Area (ft²) | D7: Allowed Density (W/ft²) | E7: Allowance (Watts) | F7: Luminaire Name or Item Tag | G7: Watts per Luminaire | H7: # of Luminaires | I7: Total Design Watts
B8: Same list as Table I column 02 | D8: Autofill based on Primary Function (in 02) | E8: =C8*D8 -> #VALUE! | F8: Drop down from Table F | G8: Autofill from Table F based on 06 | I8: =G8*H8 -> #VALUE!
A9: Total Allowance (Watts) for all Areas: | E9: =SUM(E8) -> #VALUE! | F9: Total Design Watts for all Areas: | I9: =SUM(I8) -> #VALUE!
A11: Percent of Indoor Lighting Power Allowance: | I11: =(I9/E9) -> #VALUE!

Sheet S.Daylight PAF
A1: S. DAYLIGHT DESIGN POWER ADJUSTMENT FACTOR (PAF)
A2: This table documents clerestories, horizontal slats or light shelves meet the requirements in §140.3(d)/§170.2(e)2B if a Power Adjustment Factor was claimed on Table P. These features must be documented on the architectural plans or where appropriate within the construction documents. This PAF also must be verified in the field with an acceptance test per Table U.
A3: 01 | B3: Compliance Strategy | E3: see dropdown
A4: Clerestory Fenestration
B5: Yes | C5: Not Applicable | D5: Requirement
A6: 02 | B6: ¨ | D6: Installed on East, West or South façade
A7: 03 | B7: ¨ | D7: Head height >= 10ft above finished floor
A8: 04 | B8: ¨ | D8: Glazing height >= 0.10 x head height
A9: 05 | B9: ¨ | C9: ¨ | D9: Operable shading on clerestory is controlled seperately from other shading
A10: Interior and Exterior Horizontal Slats
B11: Yes | C11: Not Applicable | D11: Requirement
A12: 06 | B12: ¨ | D12: Installed on East or West façade with 20-30% WWR
A13: 07 | B13: ¨ | D13: Exterior slats level or sloped downward from fenestration. Interior slats level or sloped upward from fenestration. Slats are permanently mounted and not adjustable.
A14: 08 | B14: ¨ | D14: Slats have a Projection Factor per Table 140.3-E/170.2-N Daylighting Devices and extend the entire height of the vertical fenestration and beyond each side of the window jamb by a distance >= their horizontal projection. Slats do not need to extend beyond the jamb if they are located entirely within the fenestration rough opening or a fin is located at the jamb and extends vertically the entire height of the jamb and horizontally the entire depth of the projection.
A15: 09 | B15: ¨ | C15: ¨ | D15: Slats have a minimum Distance Factor of 0.3 calculated per §140.3(d)/§170.2(e)2Bxii
A16: 10 | B16: ¨ | D16: Slats have a minimum Visible Reflectance of 0.50 tested in accordance with ASTM E903, and are either opaque or have a maximum Visible Transmittance of 0.03 tested in accordance with ASTM E1175
A17: 11 | B17: Location of slat design in construction documents:
A18: Interior and Exterior Light Shelves
B19: Yes | C19: Not Applicable | D19: Requirement
A20: 12 | B20: ¨ | C20: ¨ | D20: Where there is vertical fenestration area below the light shelf, both interior and exterior light shelves shall be installed.
A21: 13 | B21: ¨ | D21: Light shelves installed adjacent to clerestory fenestration on south façade with > 30% WWR and with a head height <= 1ft below the finished ceiling.
A22: 14 | B22: ¨ | D22: Exterior shelves level or sloped downward from fenestration. Interior shelves level or sloped upward from fenestration.
A23: 15 | B23: ¨ | D23: Shelves have a Projection Factor per Table 140.3-D Daylighting Devices and extend beyond each side of the window jamb by a distance >= their horizontal projection.
A24: 16 | B24: ¨ | C24: ¨ | D24: Shelves have a minimum Distance Factor of 0.3 calculated per §140.3(d)/§170.2(e)2Bxii
A25: 17 | B25: ¨ | D25: Shelves have a top surface with a minimum Visible Reflectance of 0.50 tested in accordance with ASTM E903, or an exterior light shelf installed > 2ft below the clerestory sill.
A26: 18 | B26: Location of light shelf design in construction documents:
E29: Compliance Strategy Dropdown
E30: Clerestories | H30: < Opens Clerestory "subtable" (rows 4-9)
E31: Horizontal Slats | H31: < Opens Horizontal Slats "subtable" (rows 10-16)
E32: Light Shelves | H32: < Opens Clerestory "subtable" (rows 4-9) AND Light Shelf subtable (Row 17-24)

Sheet T. Dwelling Units
B1: User input | G1: auto calculated | I1: From another Table | N1: From look up table
A2: This entire table is new for 2022
A3: T. DWELLING UNIT LIGHTING
A4: This table documents compliance with mandatory requirements for dwelling unit indoor lighting per §160.5(a) and §180.2(b)4A for alterations. Lighting systems in common use areas providing shared provisions for living, eating, cooking, or sanitation to dwelling units that would otherwise lack these provisions may document compliance with §160.5(a) in this table or may document compliance with lighting for nonresidential occupancies in other tables of this form.
A5: 01 | B5: Indicate lighting and electrical components included in multifamily dwelling units: | F5: ¨ Luminaires
F6: ¨ Blank Electrical Boxes
A8: Luminaires
B9: Yes | C9: Not Applicable | D9: Requirement
A10: 02 | B10: ¨ | D10: All installed luminaires and light sources shall meet the requirements in TABLE 160.5-A comply with Reference Joint Appendix JA8 and shall be certified and marked as required by JA8 EXCEPT lighting integral to exhaust fans, kitchen range hoods, bath vanity mirrors, and garage door openers, and ceiling fan kits that are subject to DOE's Appliance and Equipment Standards Program non-removable lighting attached to ceiling fans; lighting with an efficacy of 45 lumens per watt or greater and located internal to drawers, cabinetry, and linen closets with an efficacy of 45 lumens per watt or greater; or light sources below: - LED light sources installed outdoors - inseparable solid state lighting (SSL) luminaires containing colored light sources that are installed to provide decorative lighting - high intensity discharge (HID) light sources including pulse start metal halide and high pressure sodium light sources - luminaires with hardwired high frequence generator and induction lamp
A11: 03 | B11: ¨ | C11: ¨ | D11: Screw based luminaires shall contain lamps that comply with Reference Joint Appendix JA8.
A12: 04 | B12: ¨ | C12: ¨ | D12: Recessed Downlight Luminaires other than those marked for use in fire-rated installations and other than recessed luminaires installed in non-insulated ceilings shall meet all of the following requirements: - Shall not contain screw base lamp sockets; and - Have a label that certifies the luminaire is airtight with air leakage less than 2.0 cfm at 75 Pascals when tested in accordance with ASTM E283. An exhaust fan housing with integral light shall not be required to be certified airtight; and - Be sealed with a gasket or caulk between the luminaire housing and ceiling, and have all air leak paths between conditioned and unconditioned spaces sealed with a gasket or caulk, or be installed per manufacturer’s instructions to maintain airtightness between the luminaire housing and ceiling; and - Meet the clearance and installation requirements of California Electrical Code Article Section 410.116 for recessed luminaires.
A13: 05 | B13: ¨ | C13: ¨ | D13: Light Sources in Enclosed or Recessed Luminaires. Lamps and other separable light sources in enclosed or recessed luminaires shall be in compliance that are not compliant with the JA8 elevated temperature requirements, including marking requirements, shall not be installed in enclosed or recessed luminaires.
A15: Lighting Controls
B16: Yes | C16: Not Applicable | D16: Requirement
A17: 06 | B17: ¨ | D17: Lighting shall have readily accessible wall-mounted controls that allow the lighting to be manually turned ON and OFF. Ceiling fans may provide control of integrated lighting via a remote control.
A18: 07 | B18: ¨ | D18: Lighting controls shall comply with the applicable requirements of Section 110.9.
A19: 08 | B19: ¨ | C19: ¨ | D19: No controls shall bypass a dimmer, occupant sensor or vacancy sensor function where that dimmer or sensor has been installed to comply with Section160.5(a)2.
A20: 09 | B20: ¨ | C20: ¨ | D20: An Energy Management Control System (EMCS) or a multiscene programmable controller may be used to comply with dimming, occupancy, and lighting control requirements in Section 160.5(a)2 if it provides the functionality of the specified controls in accordance with Section 110.9, and the physical controls specified in in Section 160.5(a)2A. No controls shall bypass control functions of a dimmer, occupant sensor, or vacany sensor where the dimmer or sensor has been installed to comply with Section 160.5(a)2.
A21: 10 | B21: ¨ | D21: In bathrooms, garages, laundry rooms, utility rooms, and walk-in closets, at least one installed luminaire shall be controlled by an occupantcy or vacancy sensor providing automatic-off functionality.
A22: 11 | B22: ¨ | C22: ¨ | D22: For lighting internal to drawers and cabinetry with opaque fronts or doors, controls that turn light off when the drawer or door is closed shall be provided.
